<!DOCTYPE html>
<html lang="pt">
<head>
    <title>Try/Catch: Origem, Propósito e o Erro de Usá-lo como Fluxo Lógico | scovl</title>
    <meta charset="UTF-8">
<meta name="viewport" content="width=device-width, initial-scale=1.0">
<meta name="description" content="Entenda quando, por que e para que o try/catch foi criado, e por que ele não deve ser usado como controle de fluxo lógico.">


<link rel="preconnect" href="https://fonts.googleapis.com">
<link rel="preconnect" href="https://fonts.gstatic.com" crossorigin>
<link href="https://fonts.googleapis.com/css2?family=Roboto:wght@300;400;500;700&display=swap" rel="stylesheet">


<link rel="stylesheet" href="/css/styles.css">
<link rel="stylesheet" href="/css/syntax.css">


<link rel="stylesheet" href="https://cdnjs.cloudflare.com/ajax/libs/prism/1.28.0/themes/prism-tomorrow.min.css">
<link rel="stylesheet" href="https://cdnjs.cloudflare.com/ajax/libs/prism/1.28.0/themes/prism-dark.min.css">
<script src="https://cdnjs.cloudflare.com/ajax/libs/prism/1.28.0/prism.min.js"></script>
<script src="https://cdnjs.cloudflare.com/ajax/libs/prism/1.28.0/components/prism-clojure.min.js"></script>
<script src="https://cdnjs.cloudflare.com/ajax/libs/prism/1.28.0/components/prism-sql.min.js"></script>
<script src="https://cdnjs.cloudflare.com/ajax/libs/prism/1.28.0/components/prism-typescript.min.js"></script>
<script src="https://cdnjs.cloudflare.com/ajax/libs/prism/1.28.0/components/prism-javascript.min.js"></script>
<script src="https://cdnjs.cloudflare.com/ajax/libs/prism/1.28.0/components/prism-c.min.js"></script>
<script src="https://cdnjs.cloudflare.com/ajax/libs/prism/1.28.0/components/prism-java.min.js"></script>





<link rel="stylesheet" href="https://cdn.jsdelivr.net/npm/katex@0.16.0/dist/katex.min.css">
<script defer src="https://cdn.jsdelivr.net/npm/katex@0.16.0/dist/katex.min.js"></script>
<script defer src="https://cdn.jsdelivr.net/npm/katex@0.16.0/dist/contrib/auto-render.min.js"></script>

<script>
    document.addEventListener("DOMContentLoaded", function() {
        renderMathInElement(document.body, {
            delimiters: [
                {left: '$$', right: '$$', display: true},
                {left: '$', right: '$', display: false},
                {left: '\\(', right: '\\)', display: false},
                {left: '\\[', right: '\\]', display: true}
            ]
        });
    });
</script>



<script src="https://cdn.jsdelivr.net/npm/mermaid@10/dist/mermaid.min.js"></script>
<script>
    document.addEventListener("DOMContentLoaded", function() {
        mermaid.initialize({
            startOnLoad: true,
            theme: 'light',
            align: 'center'
        });
    });
</script>
 
</head>
<body>
    <div class="container">
        
        
        <header class="site-header">
    <div class="header-inner">
        <div class="site-branding">
            <a href="https://scovl.github.io/" class="site-title">scovl</a>
        </div>
        
        <nav class="site-nav">
            <ul>
                
                
                <li>
                    <a href="/page/about/" class="">
                        About
                    </a>
                </li>
                
                <li>
                    <a href="/page/contact/" class="">
                        Contact
                    </a>
                </li>
                
            </ul>
        </nav>
    </div>
</header> 
        
        
        
        <main>
            
<article class="post">
    <header class="post-header">
        <h1 class="post-title">Try/Catch: Origem, Propósito e o Erro de Usá-lo como Fluxo Lógico</h1>
        <div class="post-meta">
            
            <time datetime="2025-05-14T16:31:45-03:00">
                Wed, May 14, 2025
            </time>
            
            
            
            <span class="post-author">por Vitor Lobo Ramos</span>
            
            
            
            <div class="post-tags">
                
                <a href="/tags/tratamento-de-erros/" class="tag">tratamento de erros</a>
                
                <a href="/tags/exce%C3%A7%C3%B5es/" class="tag">exceções</a>
                
                <a href="/tags/javascript/" class="tag">javascript</a>
                
                <a href="/tags/typescript/" class="tag">typescript</a>
                
                <a href="/tags/rust/" class="tag">rust</a>
                
                <a href="/tags/clojure/" class="tag">clojure</a>
                
                <a href="/tags/zig/" class="tag">zig</a>
                
                <a href="/tags/boas-pr%C3%A1ticas/" class="tag">boas práticas</a>
                
            </div>
            
            
            
            <div class="reading-time">
                Estimated reading time: 79 min
            </div>
            
            
            
            <div class="post-description">
                Entenda quando, por que e para que o try/catch foi criado, e por que ele não deve ser usado como controle de fluxo lógico.
            </div>
            
        </div>
    </header>
    
    <div class="post-content content-wrapper">
        <p>O conceito de <a href="https://en.wikipedia.org/wiki/Exception_handling">tratamento de exceções</a>, incluindo o <code>try/catch</code>, surgiu nos anos 70 com linguagens como <strong><a href="https://en.wikipedia.org/wiki/PL/I">PL/I</a></strong> e <strong><a href="https://en.wikipedia.org/wiki/Ada_%28programming_language%29">Ada</a></strong>, que criaram formas mais organizadas de lidar com erros. Antes disso, os programas usavam <a href="https://en.wikipedia.org/wiki/Return_code">códigos de retorno</a> ou checagens manuais, o que deixava o código cheio de bugs e difícil de manter. A ideia era simples: separar o que o programa faz normalmente de como ele lida com as coisas que dão errado, como falhas de hardware, problemas de <a href="https://en.wikipedia.org/wiki/Input/output">entrada/saída</a> ou quando alguém tenta <a href="https://en.wikipedia.org/wiki/Division_by_zero">dividir por zero</a>.</p>
<p>O <code>try/catch</code> que a gente conhece hoje (<a href="https://isocpp.org/wiki/faq/exceptions">ISO C++ Standard - Exception Handling</a>) se popularizou com <strong><a href="https://en.wikipedia.org/wiki/C%2B%2B#Exception_handling">C++</a></strong> (nos anos 80) e <strong><a href="https://en.wikipedia.org/wiki/Java_%28programming_language%29#Exception_handling">Java</a></strong> (1995), e depois foi adotado pelo <a href="https://en.wikipedia.org/wiki/JavaScript#Exception_handling">JavaScript</a> (<a href="https://en.wikipedia.org/wiki/ECMAScript">ECMAScript 3</a>, 1999). Ele foi feito para pegar <strong><a href="https://en.wikipedia.org/wiki/Exception_%28computer_science%29">exceções</a></strong> — coisas inesperadas que interrompem o programa, tipo quando a internet cai, quando acaba a memória do computador (ex: <code>std::bad_alloc</code>) ou quando o programa tenta acessar dados que não existem — permitindo que os devs tratassem esses problemas sem o programa travar.</p>
<p>Na época, o objetivo era ter uma forma confiável de lidar com <strong><a href="https://en.wikipedia.org/wiki/Fault_tolerance">erros que ninguém consegue prever</a></strong> em sistemas complexos, garantindo que o programa pudesse se recuperar ou pelo menos falhar &ldquo;de boa&rdquo; (gracefully). O <code>try/catch</code> foi inspirado pela ideia de <strong><a href="https://en.wikipedia.org/wiki/Fault_tolerance">tolerância a falhas</a></strong>, comum em <a href="https://en.wikipedia.org/wiki/Operating_system#Reliability">sistemas operacionais</a> e aplicações críticas, onde o serviço não pode parar.</p>
<blockquote>
<p><strong>Nota:</strong> Quando falamos que algo falha &ldquo;gracefully&rdquo; ou &ldquo;de boa&rdquo;, queremos dizer que o programa quebra de um jeito controlado, sem explodir todo o sistema.</p></blockquote>
<p>Um ponto importante: o tratamento de exceções foi criado como uma alternativa aos jeitos antigos de <a href="https://en.wikipedia.org/wiki/Error_handling">verificar erros</a>, não como uma ferramenta para controlar o <a href="https://en.wikipedia.org/wiki/Control_flow">fluxo normal</a> do programa. Linguagens como <a href="https://en.wikipedia.org/wiki/CLU_%28programming_language%29">CLU</a>, desenvolvida no <a href="https://en.wikipedia.org/wiki/Massachusetts_Institute_of_Technology">MIT</a> nos anos 70, já deixavam isso bem claro, estabelecendo as bases do que viria a ser o modelo de exceções que usamos hoje.</p>
<p>Neste artigo, vamos explorar de onde veio o <code>try/catch</code>, para que ele foi criado originalmente e por que usá-lo para controlar o fluxo lógico do programa é uma péssima ideia. Embora o <code>try/catch</code> seja uma ferramenta poderosa para lidar com erros, ele foi feito para situações excepcionais, e não para gerenciar a lógica do negócio.</p>
<h2 id="sumário">Sumário</h2>
<ul>
<li><a href="/2025/05/14/trycatch/#prop%c3%b3sito-do-trycatch">Propósito do Try/Catch</a>
<ul>
<li><a href="/2025/05/14/trycatch/#problemas-com-c%c3%b3digos-de-erro">Problemas com Códigos de Erro</a></li>
<li><a href="/2025/05/14/trycatch/#separa%c3%a7%c3%a3o-de-preocupa%c3%a7%c3%b5es">Separação de Preocupações</a></li>
<li><a href="/2025/05/14/trycatch/#erros-n%c3%a3o-podem-ser-ignorados">Erros Não Podem Ser Ignorados</a></li>
<li><a href="/2025/05/14/trycatch/#raii-e-seguran%c3%a7a-de-exce%c3%a7%c3%a3o">RAII e Segurança de Exceção</a>
<ul>
<li><a href="/2025/05/14/trycatch/#como-o-raii-protege-seus-recursos">Como o RAII Protege Seus Recursos</a></li>
<li><a href="/2025/05/14/trycatch/#exemplos-de-raii-na-biblioteca-padr%c3%a3o">Exemplos de RAII na Biblioteca Padrão</a></li>
</ul>
</li>
</ul>
</li>
<li><a href="/2025/05/14/trycatch/#por-que-usar-trycatch-como-fluxo-l%c3%b3gico-%c3%a9-errado">Por que Usar Try/Catch como Fluxo Lógico é Errado</a>
<ul>
<li><a href="/2025/05/14/trycatch/#contrato-impl%c3%adcito">Contrato Implícito</a></li>
<li><a href="/2025/05/14/trycatch/#interrup%c3%a7%c3%a3o-abrupta-do-fluxo">Interrupção Abrupta do Fluxo</a></li>
<li><a href="/2025/05/14/trycatch/#exception-safety-e-fun%c3%a7%c3%b5es-make">Exception Safety e Funções Make</a></li>
<li><a href="/2025/05/14/trycatch/#impacto-no-design-de-apis">Impacto no Design de APIs</a></li>
<li><a href="/2025/05/14/trycatch/#desempenho-e-custo-das-exce%c3%a7%c3%b5es">Desempenho e Custo das Exceções</a>
<ul>
<li><a href="/2025/05/14/trycatch/#o-impacto-do-noexcept-nas-otimiza%c3%a7%c3%b5es">O Impacto do <code>noexcept</code> nas Otimizações</a></li>
</ul>
</li>
</ul>
</li>
<li><a href="/2025/05/14/trycatch/#quando-usar-trycatch">Quando Usar Try/Catch?</a>
<ul>
<li><a href="/2025/05/14/trycatch/#falhas-de-sistema-e-recursos-externos">Falhas de Sistema e Recursos Externos</a></li>
<li><a href="/2025/05/14/trycatch/#valida%c3%a7%c3%a3o-de-entrada-em-apis-p%c3%bablicas">Validação de Entrada em APIs Públicas</a></li>
<li><a href="/2025/05/14/trycatch/#recupera%c3%a7%c3%a3o-de-estados-inconsistentes">Recuperação de Estados Inconsistentes</a></li>
<li><a href="/2025/05/14/trycatch/#em-ambientes-de-alto-n%c3%advel">Em Ambientes de Alto Nível</a></li>
</ul>
</li>
<li><a href="/2025/05/14/trycatch/#alternativas-ao-trycatch-para-fluxo-l%c3%b3gico">Alternativas ao Try/Catch para Fluxo Lógico</a>
<ul>
<li><a href="/2025/05/14/trycatch/#verifica%c3%a7%c3%b5es-condicionais">Verificações Condicionais</a></li>
<li><a href="/2025/05/14/trycatch/#tipos-de-resultado">Tipos de Resultado</a></li>
<li><a href="/2025/05/14/trycatch/#objetos-de-resultado">Objetos de Resultado</a></li>
<li><a href="/2025/05/14/trycatch/#valida%c3%a7%c3%b5es-pr%c3%a9vias">Validações Prévias</a></li>
<li><a href="/2025/05/14/trycatch/#abordagens-em-outras-linguagens">Abordagens em Outras Linguagens</a></li>
</ul>
</li>
<li><a href="/2025/05/14/trycatch/#boas-pr%c3%a1ticas-para-uso-do-trycatch">Boas Práticas para Uso do Try/Catch</a></li>
<li><a href="/2025/05/14/trycatch/#refer%c3%aancias">Referências</a></li>
</ul>
<h2 id="propósito-do-trycatch">Propósito do Try/Catch</h2>
<p>O <code>try/catch</code> é uma ferramenta essencial em várias linguagens como C++, criada para lidar com erros. Seu objetivo principal é ajudar os programadores a tratar problemas que acontecem durante a execução do programa de forma organizada. Bjarne Stroustrup, criador do C++, discute em seu livro <a href="https://a.co/d/3Wy2dFE">&ldquo;Programming: Principles and Practice Using C++&rdquo;</a> que as exceções foram criadas para resolver problemas fundamentais com os métodos tradicionais de retorno de códigos de erro:</p>
<ol>
<li>
<p><strong>Problemas com Códigos de Erro</strong>:</p>
<ul>
<li>O chamador pode esquecer de verificar o valor de retorno de erro.
<ul>
<li>O exemplo abaixo mostra como isso pode levar a problemas. Aqui, <code>read_int()</code> retorna um código de erro se a leitura falhar, mas o chamador não verifica o valor de retorno, resultando em um valor inválido sendo usado em uma operação:</li>
</ul>


  <pre><code class="language-c">int x = read_int();  // Se read_int() retornar um código de erro, x terá um valor inválido
int y = x * 2;       // Continuamos usando x sem verificar se houve erro</code></pre>
 </li>
</ul>
</li>
<li>
<p><strong>Separação de Preocupações</strong>:</p>
<ul>
<li>As exceções separam a detecção de erros (na função chamada) do tratamento de erros (na função chamadora)</li>
<li>Isso permite um código mais limpo, onde a lógica principal não fica poluída com verificações de erro
<ul>
<li>O exemplo abaixo mostra como o tratamento de erros pode ser centralizado em um único lugar. Pois, o tratamento de erros não está poluindo o fluxo normal de execução:</li>
</ul>


  <pre><code class="language-c">// Com try/catch - código principal limpo
try {
  processarDados();
  salvarResultados();
  enviarNotificacao();
} catch (ErroProcessamento&amp; e) {
  // Tratamento centralizado aqui
  registrarErro(e);
}</code></pre>
 </li>
</ul>
</li>
<li>
<p><strong>Erros Não Podem Ser Ignorados</strong>:</p>
<ul>
<li>Se uma exceção não for capturada, o programa terminará de forma controlada</li>
<li>Isso garante que erros críticos não passem despercebidos
<ul>
<li>Exemplo abaixo mostra como o tratamento de erros deve ser obrigatório pois, se não capturarmos a exceção, o programa terminará de forma controlada:</li>
</ul>


  <pre><code class="language-c">void funcao_que_pode_falhar() {
    // Se ocorrer um problema sério
    throw std::runtime_error(&#34;Erro crítico detectado&#34;);
    // O código abaixo nunca será executado se a exceção for lançada
    std::cout &lt;&lt; &#34;Esta linha nunca será impressa se houver erro&#34;;
}

int main() {
    // Se não capturarmos a exceção aqui
    funcao_que_pode_falhar();  // Programa terminará se a exceção for lançada
    return 0;
}</code></pre>
 </li>
</ul>
</li>
</ol>
<p>Como Stroustrup afirma: <strong>&ldquo;Se uma função encontra um erro que não consegue tratar, ela lança uma exceção. Qualquer chamador direto ou indireto pode capturar a exceção&hellip; Se nenhum chamador capturar uma exceção, o programa termina.&rdquo;</strong> Esta abordagem garante que erros críticos não possam ser ignorados acidentalmente.</p>
<h3 id="principais-usos-do-trycatch">Principais Usos do Try/Catch</h3>
<h4 id="1-lidar-com-situações-inesperadas">1. Lidar com Situações Inesperadas</h4>
<p>O <code>try/catch</code> existe principalmente para gerenciar problemas que fogem do normal. São aquelas situações que não dá para prever facilmente e que quebram o fluxo comum do programa. Alguns exemplos são:</p>
<ul>
<li>Quando o computador não consegue reservar memória (<code>std::bad_alloc</code> em C++)</li>
<li>Erros ao tentar ler ou escrever arquivos (como tentar abrir um arquivo que não existe)</li>
<li>Problemas de acesso inválido a dados (embora muitas vezes o sistema operacional mate o programa antes do <code>try/catch</code> poder fazer algo)</li>
</ul>
<p>Embora não dê para capturar diretamente falhas de hardware, podemos pegar os erros que elas causam (como um erro de leitura de disco). Vamos ver um exemplo em C++ que mostra como lidar com uma falha ao tentar alocar muita memória (algo que você não tem como saber antecipadamente se vai funcionar ou não):</p>


  <pre><code class="language-c">#include &lt;iostream&gt;
#include &lt;vector&gt;
#include &lt;new&gt;       // Necessário para std::bad_alloc
#include &lt;limits&gt;    // Necessário para std::numeric_limits

int main() {
    std::cout &lt;&lt; &#34;Iniciando o programa...&#34; &lt;&lt; std::endl;

    try {
        std::cout &lt;&lt; &#34;Dentro do bloco try: Tentando alocar uma quantidade excessiva de memória...&#34; &lt;&lt; std::endl;

        // Tentaremos alocar um vetor de &#39;unsigned long long&#39; com o maior tamanho possível
        // que std::vector pode tentar gerenciar, ou um tamanho explicitamente gigantesco.
        // Isto tem uma alta probabilidade de falhar e lançar std::bad_alloc.
        // O valor exato para causar falha depende do sistema e da memória disponível.
        // Usar std::numeric_limits&lt;std::size_t&gt;::max() diretamente com &#39;new&#39; é mais garantido
        // para estourar a memória do que com std::vector, que pode ter suas próprias limitações internas.

        // Exemplo com &#39;new&#39;:
        unsigned long long* array_gigante = new unsigned long long[std::numeric_limits&lt;std::size_t&gt;::max() / sizeof(unsigned long long) &#43; 1];

        // Se a linha acima não lançar exceção (altamente improvável):
        std::cout &lt;&lt; &#34;Alocação de memória (improvavelmente) bem-sucedida!&#34; &lt;&lt; std::endl;
        delete[] array_gigante; // Liberar memória se alocada

    } catch (const std::bad_alloc&amp; e) {
        // Captura ESPECIFICAMENTE a exceção std::bad_alloc
        std::cerr &lt;&lt; &#34;\n--- Condição Excepcional Capturada! ---&#34; &lt;&lt; std::endl;
        std::cerr &lt;&lt; &#34;Tipo de Exceção: std::bad_alloc&#34; &lt;&lt; std::endl;
        std::cerr &lt;&lt; &#34;Mensagem: &#34; &lt;&lt; e.what() &lt;&lt; std::endl;
        std::cerr &lt;&lt; &#34;Detalhe: Falha ao tentar alocar a memória solicitada.&#34; &lt;&lt; std::endl;
        std::cerr &lt;&lt; &#34;O programa não pode continuar com esta operação, mas encerrou de forma controlada.&#34; &lt;&lt; std::endl;
        // Aqui, poderíamos registrar o erro, tentar uma estratégia alternativa com menos memória,
        // ou simplesmente informar o usuário e encerrar.
        return 1; // Indica que o programa terminou com erro
    } catch (const std::exception&amp; e) {
        // Captura outras exceções que herdam de std::exception (boa prática)
        std::cerr &lt;&lt; &#34;\n--- Outra Condição Excepcional Padrão Capturada! ---&#34; &lt;&lt; std::endl;
        std::cerr &lt;&lt; &#34;Mensagem: &#34; &lt;&lt; e.what() &lt;&lt; std::endl;
        return 1; // Indica erro
    }

    std::cout &lt;&lt; &#34;\nPrograma encerrado normalmente (só será impresso se nenhuma exceção for lançada ou se o catch não sair).&#34; &lt;&lt; std::endl;
    return 0; // Indica sucesso
}</code></pre>
 <p>Stroustrup enfatiza que exceções são um mecanismo para lidar com erros que não podem ser gerenciados através de simples valores de retorno, especialmente quando a função chamada não pode completar sua tarefa fundamental. O exemplo acima com <code>std::bad_alloc</code> ilustra perfeitamente esse princípio: quando a alocação de memória falha, a função não tem como retornar um ponteiro válido, então ela lança uma exceção para sinalizar essa condição excepcional.</p>
<h3 id="12-raii-e-segurança-de-exceção">1.2 RAII e Segurança de Exceção</h3>
<p>O C++ adota uma abordagem poderosa para gerenciamento de recursos chamada <a href="https://en.wikipedia.org/wiki/Resource_acquisition_is_initialization"><strong>RAII</strong></a> (Resource Acquisition Is Initialization), que é fundamental para escrever código seguro contra exceções. A ideia central é simples, porém poderosa:</p>
<ol>
<li><strong>Aquisição de Recurso é Inicialização</strong>: Recursos (memória, arquivos, locks) são adquiridos no construtor de um objeto e liberados automaticamente no destrutor.</li>
<li><strong>Stack Unwinding Garantido</strong>: Quando uma exceção é lançada, o C++ garante que os destrutores de todos os objetos locais na pilha sejam chamados, liberando os recursos adequadamente.</li>
</ol>
<h4 id="como-o-raii-protege-seus-recursos">Como o RAII Protege Seus Recursos</h4>
<p>O RAII é particularmente eficaz em cenários de exceções porque:</p>
<ul>
<li><strong>Segurança contra vazamentos</strong>: Mesmo que uma exceção seja lançada, os recursos são liberados corretamente quando os objetos locais saem do escopo.</li>
<li><strong>Código mais limpo</strong>: Elimina a necessidade de blocos <code>try/finally</code> ou verificações de erro repetitivas.</li>
<li><strong>Segurança de exceção forte</strong>: Garante que os objetos estejam sempre em um estado consistente, mesmo quando ocorrem erros.</li>
</ul>
<p>O RAII é a pedra angular do gerenciamento de recursos em C++, permitindo que os recursos sejam gerenciados de forma segura e previsível, mesmo na presença de exceções.</p>
<h4 id="exemplos-de-raii-na-biblioteca-padrão">Exemplos de RAII na Biblioteca Padrão</h4>
<p>A biblioteca padrão do C++ está repleta de exemplos de RAII:</p>
<ul>
<li><code>std::vector</code>, <code>std::string</code>: Gerenciam sua própria memória</li>
<li><code>std::ifstream</code>, <code>std::ofstream</code>: Abrem e fecham arquivos automaticamente</li>
<li><code>std::unique_ptr</code>, <code>std::shared_ptr</code>: Gerenciam memória alocada dinamicamente</li>
<li><code>std::lock_guard</code>, <code>std::unique_lock</code>: Gerenciam locks de thread</li>
</ul>
<p>Esses tipos garantem que, mesmo que ocorra uma exceção, os recursos serão liberados corretamente, evitando vazamentos de memória, arquivos abertos e deadlocks. Por isso, é uma boa prática usar RAII para gerenciar recursos em C++. Por exemplo, ao invés de usar <code>try/catch</code> para lidar com falhas de leitura de arquivo, podemos usar RAII para garantir que o arquivo seja fechado corretamente, mesmo que ocorra uma exceção:</p>


  <pre><code class="language-c">#include &lt;iostream&gt;
#include &lt;memory&gt;
#include &lt;fstream&gt;
#include &lt;stdexcept&gt;

class ArquivoLogger {
    std::ofstream arquivo;
    
public:
    explicit ArquivoLogger(const std::string&amp; nome) 
        : arquivo(nome) {
        if (!arquivo.is_open()) {
            throw std::runtime_error(&#34;Não foi possível abrir o arquivo: &#34; &#43; nome);
        }
        std::cout &lt;&lt; &#34;Arquivo aberto com sucesso!&#34; &lt;&lt; std::endl;
    }
    
    ~ArquivoLogger() {
        if (arquivo.is_open()) {
            arquivo.close();
            std::cout &lt;&lt; &#34;Arquivo fechado com sucesso!&#34; &lt;&lt; std::endl;
        }
    }
    
    void escrever(const std::string&amp; mensagem) {
        if (!arquivo) {
            throw std::runtime_error(&#34;Tentativa de escrever em arquivo fechado&#34;);
        }
        arquivo &lt;&lt; mensagem &lt;&lt; std::endl;
    }
};

void processarDados() {
    // Exemplo de ponteiro inteligente (smart pointer) para gerenciar memória
    auto dados = std::make_unique&lt;int[]&gt;(100);
    
    // Exemplo de RAII com arquivo
    ArquivoLogger logger(&#34;log.txt&#34;);
    
    // Se esta linha lançar uma exceção, o destrutor de logger será chamado
    // automaticamente, garantindo que o arquivo seja fechado corretamente
    logger.escrever(&#34;Processando dados...&#34;);
    
    // Código que pode lançar exceção
    throw std::runtime_error(&#34;Erro durante o processamento&#34;);
}

int main() {
    try {
        processarDados();
    } catch (const std::exception&amp; e) {
        std::cerr &lt;&lt; &#34;Erro: &#34; &lt;&lt; e.what() &lt;&lt; std::endl;
        // Mesmo com a exceção, todos os recursos são liberados corretamente
        return 1;
    }
    return 0;
}</code></pre>
 <h3 id="13-custo-de-performance-das-exceções">1.3 Custo de Performance das Exceções</h3>
<p>Embora as exceções sejam uma ferramenta poderosa para tratamento de erros, é importante entender seu impacto no desempenho:</p>
<ol>
<li>
<p><strong>Custo de Lançamento de Exceções</strong></p>
<ul>
<li>Lançar uma exceção é uma operação cara em C++</li>
<li>Envolve a criação de um objeto de exceção e o desenrolamento da pilha</li>
<li>Pode ser ordens de magnitude mais lento que retornos de função comuns</li>
</ul>
</li>
<li>
<p><strong>Impacto no Código</strong></p>
<ul>
<li>O uso de <code>try/catch</code> pode impedir certas otimizações do compilador</li>
<li>Funções que podem lançar exceções geralmente não podem ser otimizadas tão agressivamente</li>
<li>O compilador deve gerar código para lidar com o desenrolamento da pilha</li>
</ul>
</li>
<li>
<p><strong>Boas Práticas</strong></p>
<ul>
<li>Use exceções apenas para condições excepcionais</li>
<li>Evite usar exceções para controle de fluxo</li>
<li>Considere alternativas como <code>std::optional</code> ou códigos de erro para casos onde o erro é esperado</li>
</ul>
</li>
</ol>


  <pre><code class="language-c">// Exemplo de código com verificação de erro sem exceções
std::optional&lt;int&gt; dividir(int a, int b) {
    if (b == 0) {
        return std::nullopt;  // Erro esperado
    }
    return a / b;
}

// Uso
if (auto resultado = dividir(10, 2)) {
    std::cout &lt;&lt; &#34;Resultado: &#34; &lt;&lt; *resultado &lt;&lt; &#34;\n&#34;;
} else {
    std::cout &lt;&lt; &#34;Divisão por zero!\n&#34;;
}</code></pre>
 <p>As exceções devem ser usadas para erros que impedem que uma função cumpra seu contrato, <strong>não para fluxo de controle normal</strong>. Embora as exceções tenham um custo quando lançadas, o custo de verificação de código de erro em cada chamada de função pode ser maior no caso de sucesso.</p>
<h4 id="garantias-de-exceção">Garantias de Exceção</h4>
<p>Há três níveis de garantias de exceção que uma função pode oferecer:</p>
<ol>
<li><strong>Garantia Básica</strong>: Se uma exceção for lançada, não há vazamento de recursos e os invariantes do objeto são mantidos.</li>
<li><strong>Garantia Forte (Commit-or-Rollback)</strong>: A operação é concluída com sucesso ou, se falhar, o estado do programa permanece como estava antes da chamada.</li>
<li><strong>Garantia No-throw</strong>: A função nunca lança exceções.</li>
</ol>
<h4 id="smart-pointers-raii-para-gerenciamento-de-memória">Smart Pointers: RAII para Gerenciamento de Memória</h4>
<p>Os smart pointers do C++ são exemplos primordiais de RAII para gerenciamento de memória:</p>
<ul>
<li><code>std::unique_ptr</code>: Possui um único dono e libera a memória automaticamente quando sai do escopo.</li>
<li><code>std::shared_ptr</code>: Permite múltiplos donos, liberando a memória quando o último dono é destruído.</li>
<li><code>std::weak_ptr</code>: Referência não-possuidora que não afeta o ciclo de vida do objeto.</li>
</ul>


  <pre><code class="language-c">void exemploSmartPointers() {
    // unique_ptr - liberação automática quando sair do escopo
    auto recurso = std::make_unique&lt;Recurso&gt;();
    
    // shared_ptr - contagem de referências
    auto recursoCompartilhado = std::make_shared&lt;Recurso&gt;();
    {
        auto outraReferencia = recursoCompartilhado; // Contador de referências incrementado
        // ...
    } // Contador de referências decrementado
    
    // weak_ptr - não incrementa a contagem de referências
    std::weak_ptr&lt;Recurso&gt; referenciaFraca = recursoCompartilhado;
    
    // Recuperar o recurso se ainda existir
    if (auto recurso = referenciaFraca.lock()) {
        // Usar o recurso
    }
}</code></pre>
 <p>O código começa importando algumas bibliotecas básicas: <code>&lt;iostream&gt;</code> pra mostrar mensagens, <code>&lt;new&gt;</code> pra lidar com o erro <code>std::bad_alloc</code>, e <code>&lt;limits&gt;</code> pra acessar valores máximos com <code>std::numeric_limits</code>. Dentro do bloco <code>try</code>, o código tenta algo quase impossível: alocar uma quantidade absurda de memória com <code>new</code>. A expressão usada é calculada pra estourar os limites do sistema de propósito.</p>
<p>Quando essa alocação falha (o que é praticamente garantido), o <code>new</code> dispara uma exceção <code>std::bad_alloc</code>. Nesse momento, o código dentro do <code>try</code> para na hora e o programa pula direto pro bloco <code>catch</code> que sabe lidar com esse tipo de erro. No bloco <code>catch</code>, o programa mostra uma mensagem de erro na tela e termina com código 1, que é uma forma de dizer &ldquo;deu problema, mas pelo menos terminei de forma controlada&rdquo;.</p>
<p>Se por algum milagre a alocação funcionasse, o programa mostraria uma mensagem de sucesso e liberaria a memória. Tem também um segundo <code>catch</code> como rede de segurança pra pegar outros tipos de erros que possam acontecer. Em resumo, o diagrama mostra o caminho que o programa segue:</p>


  
    
  
  <div class="mermaid">graph TD
    A[Início] --&gt; B{Entrada no try};
    B --&gt; C[Alocar Memória];
    C --&gt;|Sucesso| D[Fluxo Normal];
    C --&gt;|Falha| E[bad_alloc];
    D --&gt; F[Fim - Sucesso];
    E --&gt; G{Catch existe?};
    G --&gt;|Sim| H[Tratar Erro];
    G --&gt;|Não| I[Crash];
    H --&gt; J[Fim Controlado];

    style C fill:#f9f,stroke:#333
    style E fill:#ff9999,stroke:#333
    style H fill:#90ee90,stroke:#333
    classDef error fill:#ffcccc,stroke:#f00
    class I error</div>
 <p>O diagrama mostra o que acontece: o programa tenta algo arriscado (pedir memória demais). Se funcionar (quase impossível), tudo certo. Se falhar, o <code>catch</code> pega o problema e encerra o programa sem pânico. Sem tratamento, o programa simplesmente trava. É pra isso que o <code>try/catch</code> existe - evitar que tudo desabe quando algo inesperado acontece.</p>
<p>Esse jeito de programar, separando o &ldquo;caminho feliz&rdquo; do &ldquo;e se der ruim&rdquo;, é super útil quando seu código tem várias coisas que podem falhar. O <code>try/catch</code> deixa tudo mais organizado: a parte principal do código fica limpa e os tratamentos de erro ficam agrupados, tornando muito mais fácil entender o que está acontecendo.</p>
<hr>
<h3 id="11-tipos-específicos-de-exceção-em-c">1.1 Tipos Específicos de Exceção em C++</h3>
<p>No exemplo acima, usamos <code>std::bad_alloc</code>, mas o C++ oferece vários outros tipos de exceções padrão para diferentes situações de erro. Como Stroustrup demonstra na Seção 4.6.1 do seu livro, é uma boa prática criar tipos específicos de exceção para diferentes classes de erros. Por exemplo:</p>


  <pre><code class="language-c">#include &lt;stdexcept&gt;

// Exceção personalizada para argumentos inválidos
class ArgumentoInvalido : public std::invalid_argument {
public:
    explicit ArgumentoInvalido(const std::string&amp; msg) 
        : std::invalid_argument(msg) {}
};

// Exceção personalizada para erros de domínio
class ErroDominio : public std::runtime_error {
public:
    explicit ErroDominio(const std::string&amp; msg) 
        : std::runtime_error(msg) {}
};

// Função que usa as exceções personalizadas
double calcular_raiz_quadrada(double x) {
    if (x &lt; 0) {
        throw ArgumentoInvalido(&#34;Não existe raiz quadrada real para números negativos&#34;);
    }
    if (x &gt; 1e100) {
        throw ErroDominio(&#34;Número muito grande para cálculo preciso&#34;);
    }
    return std::sqrt(x);
}

int main() {
    try {
        double resultado = calcular_raiz_quadrada(-1);
        std::cout &lt;&lt; &#34;Resultado: &#34; &lt;&lt; resultado &lt;&lt; std::endl;
    } catch (const ArgumentoInvalido&amp; e) {
        std::cerr &lt;&lt; &#34;Erro de argumento: &#34; &lt;&lt; e.what() &lt;&lt; std::endl;
    } catch (const ErroDominio&amp; e) {
        std::cerr &lt;&lt; &#34;Erro de domínio: &#34; &lt;&lt; e.what() &lt;&lt; std::endl;
    } catch (const std::exception&amp; e) {
        std::cerr &lt;&lt; &#34;Erro inesperado: &#34; &lt;&lt; e.what() &lt;&lt; std::endl;
    }
    return 0;
}</code></pre>
 <p>Neste exemplo, criamos duas exceções personalizadas que herdam das classes base da biblioteca padrão (<code>std::invalid_argument</code> e <code>std::runtime_error</code>). Isso permite:</p>
<ol>
<li><strong>Tratamento específico</strong> para diferentes tipos de erros</li>
<li><strong>Hierarquia de exceções</strong> que pode ser explorada nos blocos <code>catch</code></li>
<li><strong>Mensagens de erro mais descritivas</strong> para cada situação</li>
<li><strong>Reutilização</strong> em diferentes partes do código</li>
</ol>
<p>A biblioteca padrão do C++ oferece várias classes de exceção úteis na biblioteca <code>&lt;stdexcept&gt;</code>, incluindo:</p>
<ul>
<li>
<p><code>std::logic_error</code> - para erros que poderiam ser detectados antes da execução</p>
<ul>
<li><code>std::invalid_argument</code> - argumento inválido</li>
<li><code>std::out_of_range</code> - acesso fora dos limites</li>
<li><code>std::length_error</code> - excede o tamanho máximo permitido</li>
</ul>
</li>
<li>
<p><code>std::runtime_error</code> - para erros que só podem ser detectados durante a execução</p>
<ul>
<li><code>std::overflow_error</code> - resultado muito grande para o tipo</li>
<li><code>std::underflow_error</code> - resultado muito pequeno para o tipo</li>
<li><code>std::range_error</code> - resultado fora do intervalo válido</li>
</ul>
</li>
</ul>
<p>Usar esses tipos específicos (ou criar os seus próprios) torna o tratamento de erros mais expressivo e seguro, permitindo que diferentes tipos de erros sejam tratados de maneiras diferentes.</p>
<hr>
<h3 id="2-separar-tratamento-de-erros-da-lógica-principal">2. Separar Tratamento de Erros da Lógica Principal</h3>
<p>Em programação, erros acontecem o tempo todo – arquivos que não existem, dados errados, memória que acaba. Como lidamos com esses problemas faz toda diferença na qualidade do nosso código. Uma dica de ouro é separar o que o programa deve fazer normalmente do que ele faz quando algo dá errado. Sem essa separação, seu código vira uma bagunça de verificações que dificulta entender o que ele realmente deveria estar fazendo. Existem dois jeitos principais de lidar com erros:</p>
<ol>
<li>
<p><strong>Sem <code>try/catch</code> (Checando tudo manualmente)</strong></p>
<ul>
<li>Você precisa verificar cada coisinha que pode dar errado.</li>
<li>O código fica cheio de <code>if/else</code> por todo lado.</li>
<li>Exemplo:


  <pre><code class="language-python">arquivo = abrir_arquivo(&#34;dados.txt&#34;)
if arquivo.erro:
    print(&#34;Ops! Arquivo não abriu!&#34;)
else:
    nome = ler_linha(arquivo)
    if nome.erro:
        print(&#34;Puxa, não consegui ler o nome!&#34;)
    else:
        idade = converter_para_inteiro(ler_linha(arquivo))
        if idade.erro:
            print(&#34;Eita, essa idade não é um número!&#34;)
        else:
            # Aqui finalmente fazemos o que importa</code></pre>
 </li>
<li><strong>Problema:</strong> Olha essa confusão! Difícil até ver onde está a lógica principal.</li>
</ul>
</li>
<li>
<p><strong>Com <code>try/catch</code> (Usando exceções)</strong></p>
<ul>
<li>Você escreve seu código como se tudo fosse dar certo.</li>
<li>Se algo falhar, o problema é jogado para um lugar específico.</li>
<li>Exemplo:


  <pre><code class="language-python">try:
    arquivo = abrir_arquivo(&#34;dados.txt&#34;)
    nome = ler_linha(arquivo)
    idade = converter_para_inteiro(ler_linha(arquivo))
    # Aqui a gente faz o que realmente importa
except ErroArquivo:
    print(&#34;Problema com o arquivo!&#34;)
except ErroConversao:
    print(&#34;Essa idade não é um número válido!&#34;)</code></pre>
 </li>
<li><strong>Vantagem:</strong> Muito mais limpo! Dá para entender facilmente o que o código deveria fazer.</li>
</ul>
</li>
</ol>
<p>O código sem <code>try/catch</code> precisa verificar erros após cada operação, criando um caminho tortuoso cheio de condicionais. Primeiro verificamos se o arquivo abriu, depois se a leitura funcionou, em seguida se o processamento deu certo - cada etapa com seu próprio tratamento de erro.</p>
<p>Em contraste, o código com <code>try/catch</code> segue um fluxo linear e limpo: abrimos o arquivo, lemos os dados, processamos e completamos a operação - tudo em sequência direta. Se algo der errado em qualquer ponto, o fluxo salta automaticamente para o bloco <code>catch</code>, onde identificamos o problema e o tratamos adequadamente.</p>
<p>Esta separação clara entre o &ldquo;caminho feliz&rdquo; e o tratamento de erros torna o código muito mais legível e fácil de manter. Você consegue entender rapidamente o que o programa deve fazer quando tudo funciona, sem se perder em uma floresta de verificações de erro. Analisando o diagrama abaixo, você pode ver como a abordagem com <code>try/catch</code> é muito mais clara e fácil de entender:</p>


  
  <div class="mermaid">graph TD
    A_Start[Início do Processo]

    subgraph Abordagem SEM Try/Catch
        direction TB
        S1[Lógica: Abrir Arquivo] --&gt; C1{Erro ao Abrir?}
        C1 -- Sim --&gt; TE1[Tratar Erro]
        TE1 --&gt; FimErro[Processo Concluído com Erro]
        C1 -- Não --&gt; S2[Lógica: Ler Nome]
        S2 --&gt; C2{Erro ao Ler?}
        C2 -- Sim --&gt; TE2[Tratar Erro]
        TE2 --&gt; FimErro
        C2 -- Não --&gt; S3[Lógica: Ler Idade]
        S3 --&gt; C3{Erro ao Converter?}
        C3 -- Sim --&gt; TE3[Tratar Erro]
        TE3 --&gt; FimErro
        C3 -- Não --&gt; S4[Lógica: Usar Dados]
        S4 --&gt; FimSucesso[Processo Concluído com Sucesso]
    end

    A_Start --&gt; SemTryCatch_Inicio
    SemTryCatch_Inicio --&gt; S1

    subgraph Abordagem COM Try/Catch
        direction TB
        TC_Try_Start --&gt; LP1[Lógica: Abrir Arquivo]
        LP1 --&gt; LP2[Lógica: Ler Nome]
        LP2 --&gt; LP3[Lógica: Ler Idade]
        LP3 --&gt; LP4[Lógica: Usar Dados]
        LP4 --&gt; FimSucesso
        
        LP1 -- Exceção --&gt; TC_Catch_Start
        LP2 -- Exceção --&gt; TC_Catch_Start
        LP3 -- Exceção --&gt; TC_Catch_Start
        
        TC_Catch_Start --&gt; TE_Geral[Tratar Exceção]
        TE_Geral --&gt; FimErro
    end

    A_Start --&gt; ComTryCatch_Inicio
    ComTryCatch_Inicio --&gt; TC_Try_Start

    classDef logicaPrincipal fill:#D5E8D4,stroke:#82B366
    classDef tratamentoErro fill:#F8CECC,stroke:#B85450
    classDef verificacaoErro fill:#FFF2CC,stroke:#D6B656
    classDef tryCatchBlock fill:#DAE8FC,stroke:#6C8EBF

    class S1,S2,S3,S4,LP1,LP2,LP3,LP4 logicaPrincipal
    class C1,C2,C3 verificacaoErro
    class TE1,TE2,TE3,TE_Geral tratamentoErro
    class TC_Try_Start,TC_Try_FimSucesso,TC_Catch_Start tryCatchBlock</div>
 <p>A abordagem sem <code>try/catch</code> (à esquerda) é cheia de verificações de erro a cada passo com muitos <code>if</code>s e <code>else</code>s. Isso deixa o código bagunçado e difícil de acompanhar. Você acaba repetindo código de tratamento de erro várias vezes.</p>
<p>Já usando <code>try/catch</code> (à direita), você coloca todas as operações principais juntas no bloco <code>try</code>. Se algo der errado, o programa pula direto para o <code>catch</code> - simples assim! Seu código fica muito mais limpo e organizado.</p>
<p>Olhando o diagrama, dá pra ver na hora a diferença: o lado esquerdo parece uma árvore toda ramificada com desvios para todo lado, enquanto o lado direito segue um caminho mais direto, com os problemas tratados separadamente. É como comparar uma rota cheia de desvios com uma estrada expressa que tem saídas de emergência bem sinalizadas!</p>
<hr>
<h3 id="3-recuperação-controlada">3. <strong>Recuperação Controlada</strong></h3>
<p>Usar <code>try/catch</code> ajuda a <strong>separar claramente</strong> a lógica principal do tratamento de erros, tornando o código mais <strong>organizado e legível</strong>. Enquanto isso, a abordagem sem <code>try/catch</code> exige verificações manuais, poluindo o fluxo do programa.</p>
<p>Um dos objetivos mais importantes no tratamento de erros é permitir que o programa <strong>se recupere de maneira controlada</strong> quando algo dá errado, em vez de simplesmente travar ou encerrar abruptamente. Essa prática é conhecida como <strong>&ldquo;graceful recovery&rdquo;</strong> e é essencial para criar sistemas <strong>robustos, confiáveis e amigáveis ao usuário</strong>.  Porque isso é importante?</p>
<ol>
<li>
<p><strong>Evita Falhas Catastróficas</strong></p>
<ul>
<li>Um programa que &ldquo;quebra&rdquo; sem tratamento adequado pode corromper dados, deixar recursos abertos (como arquivos ou conexões de rede) ou causar comportamentos inesperados.</li>
<li>Exemplo: Se um aplicativo de banco falhar no meio de uma transferência, sem rollback ou registro adequado, o dinheiro poderia ser debitado sem ser creditado no destino.</li>
</ul>
</li>
<li>
<p><strong>Melhora a Experiência do Usuário</strong></p>
<ul>
<li>Em vez de mostrar mensagens genéricas (como <em>&ldquo;O programa parou de funcionar&rdquo;</em>), um tratamento adequado permite:
<ul>
<li>Exibir <strong>erros claros e acionáveis</strong> (ex: <em>&ldquo;Arquivo não encontrado. Verifique o caminho e tente novamente.&rdquo;</em>).</li>
<li>Oferecer <strong>alternativas</strong> (ex: <em>&ldquo;Deseja recriar o arquivo de configuração?&rdquo;</em>).</li>
</ul>
</li>
</ul>
</li>
<li>
<p><strong>Facilita Diagnóstico e Manutenção</strong></p>
<ul>
<li>Quando um erro ocorre, é crucial <strong>registrar informações detalhadas</strong> (logging) para que os desenvolvedores possam analisar e corrigir o problema. Exemplo: Um log pode incluir:


  <pre><code class="language-plaintext">[ERRO] 2024-01-15 14:30: Falha ao ler arquivo &#34;dados.json&#34;.  
Motivo: Permissão negada.  
Stack trace: linha 42, módulo file_reader.py  </code></pre>
 </li>
</ul>
</li>
</ol>
<p>O diagrama abaixo contrasta duas formas de lidar com falhas em sistemas: uma abordagem <strong>básica</strong> (que interrompe o fluxo) e uma <strong>resiliente</strong> (que prioriza continuidade e clareza). Por exemplo, em um programa que processa arquivos:</p>
<ul>
<li>
<p><strong>Abordagem Básica:</strong><br>
Se o arquivo não existir, o programa é interrompido sem explicações úteis ou registros.</p>
</li>
<li>
<p><strong>Abordagem Resiliente:</strong><br>
O erro é documentado, o usuário recebe orientação (ex: <em>&ldquo;Arquivo não encontrado. Verifique o nome ou selecione outro&rdquo;</em>), e o sistema pode se recuperar automaticamente quando possível.</p>
</li>
</ul>


  
  <div class="mermaid">graph TD
    A[Iniciar Operação] --&gt; B[Tentar Processo]
    B --&gt; C{Operação falhou?}
    C -- Sim --&gt; D[Registrar causa e contexto]
    D --&gt; E{Recuperação automática possível?}
    E -- Sim --&gt; F[Executar alternativa]
    F --&gt; G[Continuar fluxo principal]
    E -- Não --&gt; H[Encerrar com feedback claro]
    C -- Não --&gt; I[Concluir com sucesso]</div>
 <p>A abordagem <strong>Fluxo Resiliente</strong> é preferível pois mantém um histórico detalhado para diagnóstico, comunica falhas em linguagem acessível e tenta soluções alternativas antes de falhar.</p>
<p>Já a abordagem <strong>Fluxo Básico</strong> tem graves limitações, como interrupção sem contexto, perda de informações sobre a falha e experiência frustrante para usuários.</p>
<p>A abordagem resiliente no tratamento de erros é crucial porque mantém a confiança do usuário e a integridade do sistema. Quando problemas ocorrem, como no exemplo de leitura de arquivo em Node.js, em vez de simplesmente falhar, o sistema registra o erro detalhadamente (<code>logger.error</code>) e tenta uma recuperação automática (criando uma configuração padrão quando o arquivo não existe). Isso permite que os usuários entendam o problema e, quando possível, continuem usando o aplicativo sem interrupções bruscas, transformando uma experiência potencialmente frustrante em uma oportunidade de resolução transparente.</p>


  <pre><code class="language-javascript">const fs = require(&#39;fs&#39;).promises;
const path = require(&#39;path&#39;);

// Configuração padrão que será usada se o arquivo não existir
const DEFAULT_CONFIG = {
    port: 3000,
    environment: &#39;development&#39;,
    logLevel: &#39;info&#39;
};

/**
 * Lê o arquivo de configuração ou cria um padrão se não existir
 * @returns {Promise&lt;Object&gt;} Objeto de configuração
 */
async function loadConfig() {
    const configPath = path.join(__dirname, &#39;config.json&#39;);
    
    try {
        // Tenta ler o arquivo de configuração
        const data = await fs.readFile(configPath, &#39;utf8&#39;);
        return JSON.parse(data);
    } catch (error) {
        // Se o arquivo não existir (código de erro &#39;ENOENT&#39;)
        if (error.code === &#39;ENOENT&#39;) {
            console.log(&#39;Arquivo de configuração não encontrado. Usando configuração padrão.&#39;);
            
            // Tenta criar o arquivo com a configuração padrão
            try {
                await fs.writeFile(
                    configPath, 
                    JSON.stringify(DEFAULT_CONFIG, null, 2),
                    &#39;utf8&#39;
                );
                console.log(&#39;Arquivo de configuração padrão criado com sucesso.&#39;);
                return DEFAULT_CONFIG;
            } catch (writeError) {
                // Se não conseguir escrever o arquivo, loga o erro mas continua com a configuração em memória
                console.error(&#39;Erro ao criar arquivo de configuração padrão:&#39;, writeError.message);
                return DEFAULT_CONFIG;
            }
        } 
        // Se houver erro de sintaxe no JSON
        else if (error instanceof SyntaxError) {
            console.error(&#39;Erro ao analisar o arquivo de configuração:&#39;, error.message);
            console.log(&#39;Usando configuração padrão devido ao erro.&#39;);
            return DEFAULT_CONFIG;
        }
        // Para outros erros (como permissão), relança para ser tratado em um nível superior
        throw error;
    }
}

// Exemplo de uso
async function startApplication() {
    try {
        const config = await loadConfig();
        console.log(&#39;Configuração carregada:&#39;, config);
        // Inicia o servidor com a configuração carregada
        // startServer(config);
    } catch (error) {
        // Tratamento de erros fatais
        console.error(&#39;Falha crítica ao carregar a configuração:&#39;, error.message);
        console.error(&#39;Encerrando o aplicativo...&#39;);
        process.exit(1); // Encerra o processo com código de erro
    }
}

startApplication();</code></pre>
 <p>O exemplo em código demonstra três pilares da resiliência: registro preciso de erros, recuperação condicional e comunicação clara com o usuário. Quando o arquivo <code>config.json</code> não é encontrado (erro <code>ENOENT</code>), o sistema cria uma configuração padrão, mantendo a operação. Para erros mais graves, ele informa o usuário de forma não técnica e encerra o processo de forma controlada (<code>process.exit(1)</code>). Essa abordagem contrasta com sistemas frágeis que simplesmente crasham, pois aqui cada falha é classificada e tratada conforme sua gravidade, seguindo práticas como fail-fast e padronização de códigos de erro.</p>
<hr>
<h3 id="4-proteger-recursos-críticos">4. Proteger Recursos Críticos</h3>
<p>O <code>try/catch</code> é essencial para <strong>proteger recursos importantes</strong> do seu programa. Pense em recursos como arquivos abertos, <a href="https://pt.wikipedia.org/wiki/Mutex"><strong>mutexes</strong></a> (que evitam que duas partes do código acessem algo ao mesmo tempo), conexões de banco de dados ou de rede. Sem proteção adequada, você pode acabar com vazamentos de recursos ou travamentos.</p>
<p>Em C++, isso é resolvido de forma elegante com o padrão <a href="https://en.cppreference.com/w/cpp/language/raii"><strong>RAII</strong></a> (ou &ldquo;Aquisição de Recurso é Inicialização&rdquo;). É simples: objetos RAII cuidam automaticamente dos recursos - quando o objeto é criado, ele pega o recurso, e quando é destruído, ele libera o recurso. O legal é que quando uma exceção acontece, o C++ garante que os <a href="https://en.cppreference.com/w/cpp/language/destructor"><strong>destrutores</strong></a> desses objetos sejam chamados, liberando tudo corretamente, mesmo se algo der errado no meio do caminho.</p>
<h4 id="ponteiros-inteligentes-raii-em-ação">Ponteiros Inteligentes: RAII em Ação</h4>
<p>Os ponteiros inteligentes do C++ moderno são exemplos primordiais de RAII em ação. Eles encapsulam a alocação dinâmica de memória e garantem sua liberação automática, mesmo na presença de exceções:</p>
<ul>
<li>
<p><code>std::unique_ptr</code>: Gerencia um recurso com semântica de posse exclusiva. Quando o <code>unique_ptr</code> sai do escopo, o recurso é automaticamente liberado.</p>


  <pre><code class="language-c">void processarArquivo(const std::string&amp; caminho) {
    // O unique_ptr garante que o arquivo será fechado, mesmo se uma exceção for lançada
    auto arquivo = std::make_unique&lt;std::ifstream&gt;(caminho);
    if (!arquivo-&gt;is_open()) {
        throw std::runtime_error(&#34;Falha ao abrir o arquivo&#34;);
    }
    // Processa o arquivo...
    // Não precisa de bloco try/catch - o destrutor do unique_ptr garante o fechamento
}</code></pre>
 </li>
<li>
<p><code>std::shared_ptr</code>: Gerencia recursos que podem ter múltiplos donos, liberando o recurso apenas quando o último <code>shared_ptr</code> é destruído.</p>


  <pre><code class="language-c">class RecursoCompartilhado {
    std::shared_ptr&lt;AlgumRecurso&gt; recurso;
public:
    RecursoCompartilhado() : recurso(std::make_shared&lt;AlgumRecurso&gt;()) {}
    // O destrutor padrão é suficiente - o shared_ptr cuida da limpeza
};</code></pre>
 </li>
</ul>
<h4 id="raii-e-exceções-uma-parceria-poderosa">RAII e Exceções: Uma Parceria Poderosa</h4>
<p>O verdadeiro poder do RAII se revela quando combinado com exceções. Quando uma exceção é lançada, o C++ garante que todos os objetos locais sejam destruídos na ordem inversa de sua criação. Isso significa que:</p>
<ol>
<li><strong>Segurança de Exceção</strong>: Os recursos são sempre liberados, mesmo que uma exceção interrompa o fluxo normal do programa.</li>
<li><strong>Código Mais Limpo</strong>: Elimina a necessidade de blocos <code>try/finally</code> ou verificações de erro redundantes.</li>
<li><strong>Prevenção de Vazamentos</strong>: Garante que recursos não sejam vazados em caso de erros inesperados.</li>
</ol>


  <pre><code class="language-c">void operacaoComplexa() {
    auto recurso1 = std::make_unique&lt;Recurso&gt;();
    auto recurso2 = std::make_shared&lt;OutroRecurso&gt;();
    
    // Se esta operação lançar uma exceção, recurso1 e recurso2
    // serão limpos automaticamente quando a pilha for desenrolada
    fazerAlgoArriscado();
    
    // Não precisamos de bloco try/catch aqui - o RAII garante a limpeza
}</code></pre>
 <p>Como destacado por Scott Meyers em &ldquo;Effective Modern C++&rdquo;, o uso correto de RAII e ponteiros inteligentes reduz significativamente a complexidade do tratamento de erros, permitindo que as exceções sejam usadas exclusivamente para situações excepcionais, enquanto o gerenciamento de recursos é tratado automaticamente pelos destrutores. O código em C++ que você forneceu ilustra bem esses pontos:</p>


  <pre><code class="language-c">#include &lt;iostream&gt;
#include &lt;fstream&gt; // Para std::ifstream
#include &lt;string&gt;
#include &lt;stdexcept&gt; // Para std::runtime_error, std::ios_base::failure

// Função que pode lançar exceções de I/O
std::string lerConteudoArquivo(const std::string&amp; caminhoArquivo) {
    // Abre o arquivo. O construtor de std::ifstream pode lançar exceção
    // se exceptions() estiver configurado para failbit e a abertura falhar.
    std::ifstream arquivo(caminhoArquivo);

    // Configura o stream para lançar exceções em caso de falha (failbit)
    // ou erro irrecuperável (badbit).
    arquivo.exceptions(std::ifstream::failbit | std::ifstream::badbit);

    // Se o construtor não lançou e exceptions() foi chamado depois,
    // uma checagem explícita de is_open() seguida de um throw manual
    // poderia ser usada. Contudo, configurar exceptions() antes ou no
    // construtor é o ideal para que o próprio stream lance a exceção.
    // A chamada a exceptions() após a abertura já garante que operações subsequentes
    // como getline() também lancem exceções se falharem.
    // Se o arquivo não pôde ser aberto, e failbit foi setado, a configuração
    // de exceptions() faria com que uma exceção já tivesse sido lançada
    // na construção de &#39;arquivo&#39; ou na chamada &#39;arquivo.open()&#39;.
    // Portanto, um &#39;if (!arquivo.is_open()) throw ...&#39; aqui seria redundante
    // se &#39;exceptions&#39; estiver ativo desde o início para &#39;failbit&#39;.

    std::string conteudo;
    std::string linha;
    // std::getline pode lançar std::ios_base::failure se encontrar EOF
    // e failbit estiver setado (e exceptions ligado para failbit),
    // ou se ocorrer um erro de leitura.
    while (std::getline(arquivo, linha)) {
        conteudo &#43;= linha &#43; &#34;\n&#34;;
    }
    // arquivo.close() é chamado automaticamente pelo destrutor de std::ifstream (RAII)
    // quando &#39;arquivo&#39; sai de escopo, mesmo se uma exceção for lançada após a abertura.
    return conteudo;
}

int main() {
    try {
        // Tentativa de executar a lógica principal que pode falhar
        std::string dados = lerConteudoArquivo(&#34;meu_arquivo.txt&#34;);
        std::cout &lt;&lt; &#34;Conteúdo do arquivo:\n&#34; &lt;&lt; dados;
    } catch (const std::ios_base::failure&amp; e) { // Captura específica para erros de I/O
        // Tratamento da condição excepcional (erro de I/O)
        std::cerr &lt;&lt; &#34;Erro de I/O ao ler o arquivo: &#34; &lt;&lt; e.what() &lt;&lt; &#34; (Código: &#34; &lt;&lt; e.code() &lt;&lt; &#34;)&#34; &lt;&lt; std::endl;
        // Recuperação graciosa: informar o erro e terminar controladamente
        return 1; // Indica erro
    } catch (const std::exception&amp; e) { // Captura outras exceções padrão
        // Tratamento para outras condições excepcionais
        std::cerr &lt;&lt; &#34;Ocorreu um erro inesperado: &#34; &lt;&lt; e.what() &lt;&lt; std::endl;
        // Recuperação graciosa
        return 1; // Indica erro
    }
    // Se tudo correu bem
    return 0;
}</code></pre>
 <p>Neste exemplo, o código já espera que coisas podem dar errado ao mexer com arquivos (tipo quando o arquivo não existe ou você não tem permissão). A linha <code>arquivo.exceptions(...)</code> basicamente diz: &ldquo;ei, se algo der errado, me avise lançando um erro&rdquo;.</p>
<p>A função <code>lerConteudoArquivo</code> e o <code>try</code> no <code>main</code> fazem só o trabalho de ler o arquivo. Os blocos <code>catch</code> ficam separadinhos, cuidando só de resolver os problemas. Se der algum problema lendo o arquivo, o programa cai no <code>catch</code> específico, mostra uma mensagem útil pro usuário e termina de um jeito controlado - nada de travar ou explodir.</p>
<p>O objeto <code>std::ifstream arquivo</code> é esperto! Se o programa abrir o arquivo mas der algum problema durante a leitura, o destrutor do objeto vai ser chamado automaticamente, fechando o arquivo. É como ter alguém arrumando sua bagunça mesmo quando as coisas dão errado. No fim das contas, o <code>try/catch</code> junto com práticas como RAII te ajuda a fazer programas em C++ mais resistentes a problemas, confiáveis e fáceis de manter. É como ter um plano B sempre pronto, sem complicar seu código principal.</p>
<hr>
<h2 id="por-que-usar-trycatch-como-fluxo-lógico-é-errado">Por que Usar Try/Catch como Fluxo Lógico é Errado</h2>
<h3 id="1-violação-do-princípio-do-menor-espanto">1. Violação do Princípio do Menor Espanto</h3>
<p>Usar <code>try/catch</code> como fluxo lógico viola o princípio do menor espanto (em inglês, <a href="https://en.wikipedia.org/wiki/Principle_of_least_astonishment"><strong>Principle of Least Astonishment</strong></a> ou <strong>POLA</strong>). Este princípio de design de software afirma que um sistema deve ser projetado de forma que as ações mais comuns sejam as mais fáceis de realizar, e as ações menos comuns sejam as mais difíceis de realizar.</p>
<p>Quando usamos <code>try/catch</code> como fluxo lógico, estamos violando esse princípio. Em vez de tornar as ações mais comuns mais fáceis de realizar, estamos tornando as ações menos comuns mais fáceis de realizar. Em C++, diferente de Java, uma função não precisa declarar explicitamente quais exceções ela pode lançar. O antigo mecanismo <code>throw(TipoExcecao)</code> foi abandonado porque, na prática, não funcionava bem. Hoje em dia, usamos principalmente o especificador <code>noexcept</code>:</p>
<ul>
<li><code>noexcept</code>: É como prometer &ldquo;não vou lançar exceções, palavra de escoteiro!&rdquo; Se uma exceção escapar, o programa chama <code>std::terminate</code> (ou seja, morre na hora).</li>
<li>Sem <code>noexcept</code>: É como dizer &ldquo;posso lançar exceções, fique atento!&rdquo;</li>
</ul>
<p>O problema? Mesmo quando uma função pode lançar exceções, não existe uma lista clara de quais serão. É como um restaurante que avisa que a comida pode ter ingredientes que causam alergia, mas não diz quais! Isso cria um &ldquo;contrato implícito&rdquo; - você precisa ler a documentação ou adivinhar o que pode dar errado. Em Java, as exceções são divididas em duas categorias principais:</p>
<ol>
<li>
<p><strong>Exceções Verificadas (Checked Exceptions)</strong>:</p>
<ul>
<li>São subclasses de <code>Exception</code> (mas não de <code>RuntimeException</code>).</li>
<li>Devem ser declaradas na assinatura do método usando <code>throws</code>.</li>
<li>O compilador força o tratamento ou propagação.</li>
<li>Exemplo em Java:</li>
</ul>


  <pre><code class="language-java">import java.io.IOException;
// ... outras importações ...


public class FileProcessor {
    // O compilador força a declaração de IOException
    public String readFile(String path) throws IOException {
        // Código que pode lançar IOException
        // ...
        throw new IOException(&#34;Simulando erro de leitura&#34;); // Exemplo
    }
}</code></pre>
 </li>
<li>
<p><strong>Exceções Não Verificadas (Unchecked Exceptions)</strong>:</p>
<ul>
<li>São subclasses de <code>RuntimeException</code></li>
<li>Não precisam ser declaradas</li>
<li>O compilador não força o tratamento</li>
<li>Exemplo em Java:</li>
</ul>


  <pre><code class="language-java">public class NumberParser {
    // Não precisa declarar IllegalArgumentException
    public int parsePositiveNumber(String input) {
        int number = Integer.parseInt(input);
        if (number &lt; 0) {
            throw new IllegalArgumentException(&#34;Número deve ser positivo&#34;);
        }
        return number;
    }
}</code></pre>
 </li>
</ol>
<p>As <strong>exceções não verificadas</strong> em Java são filhas da classe <code>RuntimeException</code> e têm uma grande vantagem: você não precisa declarar que vai usá-las nem é obrigado a tratá-las com <code>try/catch</code>. O compilador não fica no seu pé durante a compilação - a responsabilidade é toda sua!</p>
<p>No exemplo do código, o método <code>parsePositiveNumber</code> pode soltar uma <code>IllegalArgumentException</code> se o número for negativo, mas você não precisa avisar isso na assinatura do método. Isso deixa seu código mais limpo e flexível, permitindo tratar erros só quando realmente importa. Claro que tem o outro lado da moeda: se você esquecer de tratar uma exceção importante, seu programa pode quebrar quando menos esperar!</p>
<p>Essas exceções não verificadas são perfeitas para situações como: &ldquo;ei, você passou um dado totalmente inválido!&rdquo; ou &ldquo;isso não deveria acontecer na lógica do programa!&rdquo;. No exemplo, quando alguém tenta passar um número negativo para uma função que só aceita positivos, é como dizer: &ldquo;olha, isso é claramente um erro seu, não meu!&rdquo;</p>
<p>O &ldquo;contrato implícito&rdquo; em C++ significa que, quando uma função usa <code>try/catch</code>, ela não diz claramente quais exceções específicas pode lançar. O <code>noexcept</code> só avisa &ldquo;posso lançar exceções&rdquo; ou &ldquo;não vou lançar nada&rdquo;, mas não detalha quais erros esperar.</p>
<blockquote>
<p><strong>Nota:</strong> O <code>noexcept</code> é um mecanismo que ajuda a garantir que uma função não lance exceções, mas ele não impede que exceções sejam lançadas. Se uma exceção for lançada em uma função <code>noexcept</code>, o comportamento é indefinido.</p></blockquote>
<p>Diferente do Java, onde o compilador te obriga a tratar certos erros (as famosas exceções verificadas), o C++ é mais relaxado. Não existe nada que force você a tratar um erro específico como <code>std::runtime_error</code> ou <code>std::out_of_range</code>. Isso dá mais liberdade, mas também mais responsabilidade. Por isso, é importante documentar claramente quais exceções uma função pode lançar. Por exemplo:</p>


  <pre><code class="language-c">#include &lt;vector&gt;
#include &lt;string&gt;
#include &lt;stdexcept&gt; // Para std::out_of_range
#include &lt;iostream&gt;

// Esta função pode lançar std::out_of_range.
// Por padrão (sem noexcept), assume-se que pode lançar exceções.
// O contrato sobre *qual* exceção é lançado é implícito ou por documentação.
// /**
//  * Retorna o elemento no índice especificado.
//  * @throws std::out_of_range se o índice estiver fora dos limites.
//  */
int getElement(const std::vector&lt;int&gt;&amp; vec, size_t index) {
    if (index &gt;= vec.size()) {
        throw std::out_of_range(&#34;Acesso fora dos limites do vetor. Índice: &#34; &#43; std::to_string(index) &#43; &#34;, Tamanho: &#34; &#43; std::to_string(vec.size()));
    }
    return vec[index];
}

// Esta função promete não lançar exceções.
// Se uma exceção tentar escapar daqui, std::terminate será chamado.
void processDataNoExcept() noexcept {
    // Lógica que é garantida (ou deveria ser) não lançar exceções
    // int x = getElement({}, 0); // ISTO SERIA UM ERRO DE DESIGN se não houvesse try/catch interno
                               // pois getElement pode lançar, violando o contrato noexcept.
}

int main_example() { // Renomeado para evitar conflito com o &#39;main&#39; anterior
    std::vector&lt;int&gt; myVec = {10, 20, 30};
    try {
        // O chamador DECIDE tratar a possível exceção.
        // O compilador não força isso como faria com checked exceptions em Java.
        int val = getElement(myVec, 5); // Tentativa de acesso inválido
        std::cout &lt;&lt; &#34;Elemento: &#34; &lt;&lt; val &lt;&lt; std::endl;
    } catch (const std::out_of_range&amp; e) {
        // Tratamento da exceção específica std::out_of_range
        std::cerr &lt;&lt; &#34;Exceção capturada (out_of_range): &#34; &lt;&lt; e.what() &lt;&lt; std::endl;
    } catch (const std::exception&amp; e) {
        // Tratamento de outras exceções que derivam de std::exception
        std::cerr &lt;&lt; &#34;Outra exceção padrão capturada: &#34; &lt;&lt; e.what() &lt;&lt; std::endl;
    }
    // ...
    return 0;
}</code></pre>
 <p>Isso significa que outros devs que usarem a função <code>getElement</code> não vão ter uma dica clara do compilador sobre quais erros podem acontecer. Eles precisam ler a documentação (como aquele comentário Doxygen) ou fuçar no código pra entender o que dá errado. Esse &ldquo;contrato implícito&rdquo; dá mais liberdade, mas também aumenta o risco de exceções não tratadas direito, já que o compilador não garante que você vai lidar com todos os tipos de erros que uma função sem <code>noexcept</code> pode soltar.</p>
<p>Já no Java, a coisa é diferente. Lá existe uma divisão clara: exceções verificadas (checked) e não verificadas (unchecked). As verificadas, que são filhas da classe <code>Exception</code> (menos as <code>RuntimeException</code>), precisam ser declaradas com <code>throws</code> na assinatura do método. Isso força você a tratar o erro com <code>try/catch</code> ou passar a bomba pra frente.</p>
<p>É como se o compilador dissesse: &ldquo;Ei, esse código pode explodir, você precisa se preparar!&rdquo;. Isso ajuda a evitar surpresas e torna o código mais seguro. Já as exceções não verificadas do Java (tipo <code>RuntimeException</code>) não precisam dessa declaração, funcionando mais parecido com o C++. Não é à toa que Bjarne Stroustrup, o criador do C++, já expressou preocupações sobre o uso excessivo de exceções. Por outro lado, Linus Torvalds, criador do Linux, é conhecido por sua forte oposição ao uso de exceções em geral, preferindo códigos de retorno explícitos no kernel do Linux.</p>
<blockquote>
<p><strong>Nota:</strong> O uso de exceções em Java é mais comum para situações excepcionais, como falhas de sistema, erros de entrada/saída (IO), ou quando algo que não deveria acontecer acontece. Já no C++, exceções são mais comuns para situações que deveriam ser tratadas na lógica do programa, como divisão por zero, acesso a índices inválidos, ou quando algo que deveria ser imutável muda.</p></blockquote>
<h3 id="2-fluxo-de-controle-obscuro">2. Fluxo de Controle Obscuro</h3>
<p>Diferente das exceções verificadas (aquelas usadas em operações de arquivo, rede, etc.), as não verificadas deixam seu código mais enxuto porque você não precisa adicionar declarações <code>throws</code> em cada método ou capturar explicitamente cada erro possível. Isso reduz a verbosidade e evita aquela cascata de tratamentos de exceção que muitas vezes acaba virando código boilerplate. O resultado é uma base de código mais limpa e focada na lógica principal do negócio.</p>
<p>No entanto, essa liberdade traz consigo uma responsabilidade maior. Como o compilador não te força a lidar com exceções não verificadas, fica totalmente a seu critério decidir onde e como tratá-las. Isso significa que você precisa ter um entendimento profundo do código que está escrevendo e dos possíveis pontos de falha. Um desenvolvedor desatento pode facilmente ignorar cenários de erro importantes, resultando em falhas catastróficas em produção que poderiam ter sido evitadas.</p>
<p>Para usar exceções não verificadas de forma eficaz, é essencial adotar boas práticas de desenvolvimento. Isso inclui documentar meticulosamente quais exceções cada método pode lançar (usando comentários JavaDoc ou equivalentes), criar testes unitários abrangentes que verifiquem tanto o caminho feliz quanto os cenários de erro, e implementar mecanismos de log e monitoramento que permitam identificar rapidamente problemas em ambientes de produção. Essas práticas ajudam a mitigar os riscos enquanto você aproveita a flexibilidade e concisão que as exceções não verificadas oferecem.</p>
<p><img src="https://disneyplusbrasil.com.br/wp-content/uploads/2021/12/Tio-Ben-Homem-Aranha.jpg" alt="tio bem"></p>
<p><strong>Mas atenção: com grandes poderes vêm grandes responsabilidades!</strong> Você precisa documentar bem seu código e fazer testes decentes, senão vai ter surpresas desagradáveis quando seu programa estiver rodando em produção.</p>
<hr>
<h3 id="2-interrupção-abrupta-do-fluxo">2. <strong>Interrupção Abrupta do Fluxo</strong></h3>
<p>Exceções cortam o fluxo normal do programa na hora, jogando o controle pro bloco <code>catch</code> mais próximo que corresponde ao tipo do erro. Em C++, isso se chama &ldquo;desempilhamento da pilha&rdquo; (<a href="https://en.wikipedia.org/wiki/Stack_unwinding">stack unwinding</a>) - um processo onde o C++ garante que os destrutores de todos os objetos com armazenamento automático (alocados na pilha) sejam chamados na ordem inversa de sua construção. Isso inclui:</p>
<ul>
<li>Objetos locais declarados dentro do bloco <code>try</code></li>
<li>Objetos locais em funções chamadas a partir do bloco <code>try</code></li>
<li>Objetos membro de classes locais</li>
</ul>
<p>O desempilhamento ocorre em todos os níveis da pilha de chamadas até encontrar um manipulador <code>catch</code> apropriado. Essa garantia de limpeza é uma das grandes forças do C++, mas também contribui para o custo de desempenho quando exceções são lançadas.</p>
<p>Essa quebra no fluxo dificulta muito entender o que o código realmente faz. Você precisa ficar imaginando vários caminhos diferentes que o programa pode seguir e como os objetos vão se comportar (tentando garantir a tal da &ldquo;segurança forte contra exceções&rdquo;). Em sistemas complicados, isso vira um quebra-cabeça mental! Olha só o diagrama:</p>


  
  <div class="mermaid">graph TD
    A[Início da Funcao/Bloco] --&gt; B[Execucao Normal]
    B --&gt;|Exception thrown| C{Unwinding}
    C --&gt; D[Busca por catch compativel]
    B --&gt;|Sem Excecao| E[Continuacao Normal]
    D --&gt;|catch encontrado| F[Execucao do Bloco Catch]
    D --&gt;|catch nao encontrado| G[Propagacao da Excecao]
    F --&gt; H[Continuacao ou Termino Controlado]
    E --&gt; H</div>
 <p>O diagrama acima mostra como uma exceção quebra o fluxo normal do código (de B para E). Quando uma exceção acontece, o programa interrompe o que estava fazendo, procura um bloco <code>catch</code> apropriado (D) e pula para lá (F), criando um desvio inesperado no caminho do programa (F → H). É como se você estivesse seguindo um mapa e, de repente, fosse teletransportado para outro lugar!</p>
<p>Quando usamos <code>try/catch</code> para situações comuns e previsíveis, estamos usando a ferramenta errada. É como usar uma britadeira para abrir uma lata de ervilhas! Situações como:</p>
<ul>
<li>Validar se um campo está preenchido</li>
<li>Verificar se um arquivo existe antes de uma operação opcional</li>
<li>Checar se um número é zero antes de uma divisão</li>
</ul>
<p>Essas são situações normais de negócio, não &ldquo;exceções&rdquo; verdadeiras. Quando misturamos essas situações comuns com erros genuínos (aqueles que realmente quebram o programa de forma inesperada), o código fica confuso. Fica difícil separar o que é um erro sério do que é apenas um caminho alternativo normal. O diagrama abaixo mostra esse uso problemático do <code>try/catch</code> para coisas simples como validação de entrada:</p>


  
  <div class="mermaid">graph TD
    A[&#34;Validação de Entrada&#34;] --&gt;|&#34;Entrada Inválida (e.g., string vazia)&#34;| B[&#34;Lança std::invalid_argument&#34;]
    A --&gt;|&#34;Entrada Válida&#34;| C[&#34;Processamento Normal&#34;]
    B --&gt; D[&#34;Bloco catch (const std::invalid_argument&amp;)&#34;]
    D --&gt; E[&#34;Trata como Fluxo Alternativo (e.g., pedir nova entrada)&#34;]
    C --&gt; F[&#34;Resultado Normal&#34;]
    E --&gt; F</div>
 <p>Em vez de usar verificações simples (como <code>if/else</code> ou retornar um <code>std::optional&lt;T&gt;</code> ou <code>std::expected&lt;T, E&gt;</code> no C++ moderno), o código sai jogando exceções pra todo lado (B → D), misturando o caminho normal com o caminho de erro. Isso não só confunde quem lê, mas também pode deixar seu programa mais lento.</p>
<p>O abuso de exceções para controlar o fluxo do programa também cria uma dependência escondida entre partes do código: quem chama a função precisa saber (e estar preparado para pegar) exceções que na verdade fazem parte da lógica normal do negócio.</p>
<p>Isso é como criar um acordo secreto: &ldquo;ei, se você chamar minha função, precisa ficar de olho em 5 tipos diferentes de exceções que eu posso lançar&rdquo;. Isso amarra os componentes de um jeito desnecessário. Debugar também vira um pesadelo, porque você precisa ficar pulando de um lugar para outro na pilha de chamadas por causa dos <code>throws</code>. O diagrama abaixo mostra como o código chamador (A) precisa ficar ligado nas exceções (X e Y) que a função interna (B) pode lançar como parte do fluxo normal:</p>


  
  <div class="mermaid">graph TD
    A[&#34;Código Chamador&#34;] --&gt; B[&#34;Função Interna (usa exceções para fluxo)&#34;]
    B --&gt;|&#34;Lança Exceção de Validação X&#34;| C[&#34;Bloco catch X em A&#34;]
    B --&gt;|&#34;Lança Exceção de Caso Y&#34;| D[&#34;Bloco catch Y em A&#34;]
    A --&gt; E[&#34;Precisa Conhecer e Tratar X e Y como resultados&#34;]
    E --&gt; F[&#34;Acoplamento a detalhes de implementação da Função Interna&#34;]</div>
 <p>Essa mistura faz com que quem chama a função precise ficar &ldquo;por dentro&rdquo; de todas as exceções que são, na verdade, apenas resultados normais que a função pode retornar. É como se você precisasse decorar um manual inteiro só para usar uma ferramenta simples! Isso amarra os códigos de um jeito desnecessário e complica muito quando você precisa fazer mudanças depois.</p>
<hr>
<h3 id="3-exception-safety-e-funções-make">3. Exception Safety e Funções Make</h3>
<p>Em C++ moderno, até mesmo a criação de objetos precisa considerar a segurança contra exceções. As funções <code>std::make_unique</code> e <code>std::make_shared</code> (introduzidas no C++11 e C++14, respectivamente) são exemplos de como o design da linguagem evoluiu para lidar com exceções de forma segura.</p>
<h4 id="o-problema-com-new-direto">O Problema com <code>new</code> Direto</h4>
<p>Considere este código aparentemente inofensivo:</p>


  <pre><code class="language-c">processar(std::shared_ptr&lt;Recurso&gt;(new Recurso), outra_funcao());</code></pre>
 <p>Este código tem um problema sutil de segurança contra exceções. A ordem de execução é a seguinte:</p>
<ol>
<li><code>new Recurso</code> aloca memória</li>
<li><code>outra_funcao()</code> é executada</li>
<li>O <code>shared_ptr</code> é construído</li>
</ol>
<p>Se <code>outra_funcao()</code> lançar uma exceção, a memória alocada pelo <code>new Recurso</code> vaza, pois o <code>shared_ptr</code> ainda não foi construído para gerenciá-la.</p>
<h4 id="a-solução-com-make_shared">A Solução com <code>make_shared</code></h4>


  <pre><code class="language-c">processar(std::make_shared&lt;Recurso&gt;(), outra_funcao());</code></pre>
 <p>Com <code>make_shared</code>, a alocação e a construção do objeto são feitas em uma única operação atômica, eliminando a possibilidade de vazamento de memória.</p>
<h4 id="por-que-isso-importa-para-o-uso-de-trycatch">Por que isso Importa para o Uso de Try/Catch</h4>
<ol>
<li>
<p><strong>Segurança por Padrão</strong>: O design de <code>make_shared</code> e <code>make_unique</code> segue o princípio de que operações devem ser seguras contra exceções por padrão.</p>
</li>
<li>
<p><strong>Separação Clara de Preocupações</strong>:</p>
<ul>
<li>Código normal lida com o fluxo de sucesso</li>
<li>Exceções são para situações excepcionais</li>
<li>O gerenciamento de recursos é automático via RAII</li>
</ul>
</li>
<li>
<p><strong>Exemplo de Uso Correto</strong>:</p>


  <pre><code class="language-c">// Bom: Exceção usada apenas para erros inesperados
try {
    auto recurso = std::make_unique&lt;Recurso&gt;();
    if (!recurso-&gt;validar()) {
        // Fluxo de negócio normal: retorno de erro, não exceção
        return Resultado::ERRO_VALIDACAO;
    }
    recurso-&gt;processar();
} catch (const std::bad_alloc&amp;) {
    // Situação excepcional: falha de alocação
    return Resultado::ERRO_MEMORIA;
}</code></pre>
 </li>
<li>
<p><strong>Impacto no Design de APIs</strong>:</p>
<ul>
<li>APIs bem desenhadas não usam exceções para fluxo normal</li>
<li>Documentam claramente quais exceções podem ser lançadas</li>
<li>Usam tipos de retorno ricos (<code>std::optional</code>, <code>std::expected</code>) para casos de erro esperados</li>
</ul>
</li>
</ol>
<p>Este exemplo mostra como o C++ moderno foi projetado para usar exceções de forma segura e eficiente, mas apenas para situações verdadeiramente excepcionais. Usar <code>try/catch</code> para controle de fluxo normal vai contra esses princípios de design e pode levar a código menos seguro e mais difícil de manter.</p>
<hr>
<h3 id="4-performance">4. Performance</h3>
<p>Lançar e pegar exceções em C++ é geralmente mais lento que usar verificações simples como <code>if/else</code> ou checar um <code>std::optional</code>. O modelo de exceções em C++ é conhecido como &ldquo;<a href="https://en.wikipedia.org/wiki/Zero-cost_abstraction">zero-cost if not thrown</a>&rdquo; (custo zero se não lançada) - ou seja, ter blocos <code>try/catch</code> no seu código quase não afeta a velocidade quando tudo corre bem. Mas quando uma exceção realmente acontece (<code>throw</code>), aí a coisa fica cara!</p>
<p>Por que é tão custoso? Porque quando você lança uma exceção, o C++ precisa fazer várias coisas complicadas:</p>
<ol>
<li>
<p><strong>Criar o Objeto de Exceção</strong>: O programa cria um objeto que representa seu erro na memória livre (heap). Mesmo que você capture por referência (<code>catch (const MyException&amp; e</code>), o objeto da exceção precisa ser alocado e construído antes do início do desempilhamento.</p>
</li>
<li>
<p><strong>Desempilhar a Pilha (Stack Unwinding)</strong>: Este é o processo mais custoso! Quando uma exceção é lançada, o C++ precisa desfazer todas as chamadas de função na pilha até encontrar um bloco <code>catch</code> apropriado. Este processo envolve:</p>
<ul>
<li>
<p><strong>Tabelas de Desenrolamento</strong>: O compilador gera tabelas estáticas (unwind tables) que mapeiam cada endereço de instrução para informações sobre como desfazer as operações nesse ponto. Essas tabelas são armazenadas em uma seção especial do executável e são consultadas em tempo de execução quando uma exceção é lançada.</p>
</li>
<li>
<p><strong>Destruição Segura de Objetos</strong>: Durante o desenrolamento, os destrutores de todos os objetos com armazenamento automático (na pilha) são chamados. Importante notar que, a partir do C++11, os destrutores são implicitamente <code>noexcept</code> por padrão. Isso significa que se um destrutor lançar uma exceção durante o desenrolamento de outra exceção, o programa terminará imediatamente chamando <code>std::terminate()</code>. Este é um comportamento de segurança que evita situações de múltiplas exceções ativas simultaneamente, que são extremamente difíceis de lidar corretamente.</p>
</li>
<li>
<p><strong>Custos de Desempenho</strong>: O processo de desenrolamento é particularmente caro porque:</p>
<ol>
<li><strong>Busca não-linear</strong>: O sistema precisa percorrer a pilha de chamadas de forma não sequencial</li>
<li><strong>Operações de sincronização</strong>: Em ambientes multi-threaded, pode haver bloqueios para garantir a segurança durante o desenrolamento</li>
<li><strong>Inibição de otimizações</strong>: O compilador precisa preservar o estado da pilha em pontos onde exceções podem ocorrer, o que impede várias otimizações</li>
</ol>
</li>
<li>
<p><strong>Implicações para o Design de Classes</strong>:</p>
<ul>
<li><strong>Nunca permita que exceções escapem de destrutores</strong> - Se o seu destrutor pode lançar exceções, você deve capturá-las e tratá-las dentro do próprio destrutor.</li>
<li><strong>Use <code>noexcept</code> explicitamente</strong> - Embora os destrutores sejam implicitamente <code>noexcept</code> desde o C++11, marcá-los explicitamente documenta sua intenção e protege contra mudanças acidentais.</li>
<li><strong>Considere a classe <code>std::uncaught_exceptions()</code></strong> - Em C++17, você pode usar esta função para detectar se está no meio do desenrolamento de uma exceção e ajustar o comportamento do seu destrutor de acordo.</li>
</ul>
</li>
<li>
<p><strong>Exemplo Prático</strong>: Considere o seguinte código que demonstra o desenrolamento em múltiplos níveis:</p>
</li>
</ul>


  <pre><code class="language-c">struct Recurso {
    Recurso() { std::cout &lt;&lt; &#34;Recurso alocado\n&#34;; }
    ~Recurso() { std::cout &lt;&lt; &#34;Recurso liberado\n&#34;; }
};

void funcao3() {
    Recurso r3;
    throw std::runtime_error(&#34;Erro em funcao3&#34;);
}

void funcao2() {
    Recurso r2;
    funcao3();
}

void funcao1() {
    Recurso r1;
    funcao2();
}

int main() {
    try {
        funcao1();
    } catch (const std::exception&amp; e) {
        std::cout &lt;&lt; &#34;Exceção capturada: &#34; &lt;&lt; e.what() &lt;&lt; &#39;\n&#39;;
    }
}</code></pre>
 <p>Quando executado, a saída será:</p>


  <pre><code class="language-">Recurso alocado  (r1)
Recurso alocado  (r2)
Recurso alocado  (r3)
Recurso liberado (r3)
Recurso liberado (r2)
Recurso liberado (r1)
Exceção capturada: Erro em funcao3</code></pre>
 <p>Mesmo que o erro tenha ocorrido em <code>funcao3()</code>, o C++ garante que todos os recursos alocados nas funções anteriores sejam liberados corretamente, na ordem inversa da sua criação.</p>
<ul>
<li>
<p><strong>Impacto no Desempenho em Cenários Reais</strong>:</p>
<ol>
<li>
<p><strong>Cenário de Alta Frequência</strong>: Em um loop que processa milhares de itens por segundo, o custo do desenrolamento pode se tornar significativo se exceções forem usadas para fluxo normal.</p>
</li>
<li>
<p><strong>Código de Tempo Real</strong>: Em sistemas de tempo real, o tempo não determinístico do desenrolamento pode violar garantias de tempo de resposta.</p>
</li>
<li>
<p><strong>Código de Baixo Nível</strong>: Bibliotecas que são chamadas frequentemente podem sofrer com o overhead adicional de ter que lidar com exceções, mesmo quando não são usadas.</p>
</li>
</ol>
</li>
<li>
<p><strong>Alternativas de Melhor Desempenho</strong>:</p>
<ul>
<li>Usar <code>std::optional</code> para valores opcionais</li>
<li>Retornar códigos de erro para casos esperados</li>
<li>Usar <code>std::expected</code> (C++23) para operações que podem falhar</li>
<li>Marcar funções como <code>noexcept</code> quando apropriado</li>
</ul>
</li>
<li>
<p><strong>Exemplo de Código Otimizado</strong>:</p>
</li>
</ul>


  <pre><code class="language-c">// Versão com exceções (mais lenta)
double calcular_raiz_quadrada(double x) {
    if (x &lt; 0) {
        throw std::invalid_argument(&#34;Número negativo&#34;);
    }
    return std::sqrt(x);
}

// Versão otimizada (mais rápida)
std::optional&lt;double&gt; calcular_raiz_segura(double x) noexcept {
    if (x &lt; 0) {
        return std::nullopt;  // Sem overhead de exceção
    }
    return std::sqrt(x);
}</code></pre>
 <p>A versão otimizada evita completamente o custo do desenrolamento da pilha para casos de erro comuns, mantendo a clareza do código.</p>
</li>
</ol>
<h3 id="o-impacto-do-noexcept-nas-otimizações">O Impacto do <code>noexcept</code> nas Otimizações</h3>
<p>Como discutido por Scott Meyers no Item 14 de &ldquo;Effective Modern C++&rdquo;, a palavra-chave <code>noexcept</code> é uma ferramenta poderosa para otimização em C++ moderno. Quando usada corretamente, ela permite que o compilador gere código significativamente mais eficiente:</p>
<ol>
<li>
<p><strong>Eliminação de Código de Desempilhamento</strong>: O compilador não precisa gerar o código para desenrolar a pilha de forma segura, já que a função promete não lançar exceções. Isso resulta em:</p>
<ul>
<li>Código binário menor</li>
<li>Melhor desempenho em tempo de execução</li>
<li>Menor overhead em caminhos de código críticos</li>
</ul>
</li>
<li>
<p><strong>Otimizações de Movimento na STL</strong>: Contêineres da STL como <code>std::vector</code> usam o <code>noexcept</code> para tomar decisões importantes de desempenho:</p>
<ul>
<li><code>std::vector::push_back</code> verifica se as operações de movimento são <code>noexcept</code></li>
<li>Se forem, usa movimentação (mais rápido)</li>
<li>Se não, recorre a cópias (mais lento)</li>
</ul>
<p>Exemplo prático com impacto direto no desempenho:</p>


  <pre><code class="language-c">class BufferOtimizado {
    std::unique_ptr&lt;int[]&gt; dados;
    size_t tamanho;
public:
    // Construtor de movimento otimizado com noexcept
    BufferOtimizado(BufferOtimizado&amp;&amp; outro) noexcept 
        : dados(std::move(outro.dados)), tamanho(outro.tamanho) {
        outro.tamanho = 0;
    }

    // Operador de atribuição de movimento otimizado
    BufferOtimizado&amp; operator=(BufferOtimizado&amp;&amp; outro) noexcept {
        if (this != &amp;outro) {
            dados = std::move(outro.dados);
            tamanho = outro.tamanho;
            outro.tamanho = 0;
        }
        return *this;
    }

    // ... outras funções
};

// Uso em um contêiner - operações de realocação serão mais eficientes
std::vector&lt;BufferOtimizado&gt; buffers;
buffers.push_back(BufferOtimizado{/*...*/});  // Usará move por causa do noexcept</code></pre>
 </li>
<li>
<p><strong>Verificação em Tempo de Compilação</strong>: Funções marcadas como <code>noexcept</code> permitem otimizações agressivas:</p>
<ul>
<li>O compilador pode fazer inlining mais agressivo</li>
<li>Pode eliminar verificações de exceções em chamadas aninhadas</li>
<li>Permite otimizações de fluxo de controle</li>
</ul>
</li>
<li>
<p><strong>Contrato de Interface</strong>: <code>noexcept</code> é parte integrante da interface de uma função:</p>
<ul>
<li>Chamadores podem verificar em tempo de compilação se uma função é <code>noexcept</code></li>
<li>A STL usa <code>std::move_if_noexcept</code> para tomar decisões de desempenho</li>
<li>Bibliotecas podem fornecer implementações diferentes baseadas em garantias de exceção</li>
</ul>
</li>
<li>
<p><strong>Segurança e Documentação</strong>: Além do desempenho, <code>noexcept</code> serve como documentação viva:</p>
<ul>
<li>Deixa claro quais funções nunca lançam exceções</li>
<li>Ajuda a prevenir bugs ao forçar o programador a pensar sobre garantias de exceção</li>
<li>Permite que ferramentas estáticas verifiquem violações de contrato</li>
</ul>
</li>
</ol>
<h3 id="o-custo-oculto-das-exceções-para-controle-de-fluxo">O Custo Oculto das Exceções para Controle de Fluxo</h3>
<p>Quando usamos exceções para controle de fluxo, criamos uma série de problemas de desempenho e manutenção que vão além do simples overhead de lançar e capturar exceções. O maior desses problemas é que perdemos a capacidade de marcar funções como <code>noexcept</code>, mesmo quando elas não lançam exceções em seu fluxo normal. Isso tem várias implicações profundas:</p>
<ol>
<li>
<p><strong>Perda de Otimizações de Movimento</strong>: Como vimos, contêineres da STL como <code>std::vector</code> verificam se as operações de movimento são <code>noexcept</code>. Se não forem, recorrem a cópias mais lentas, mesmo quando a operação de movimento seria segura.</p>
</li>
<li>
<p><strong>Código de Desempilhamento Ineficiente</strong>: Mesmo quando não lançamos exceções, o compilador ainda precisa gerar código para lidar com o desenrolar da pilha, aumentando o tamanho do binário.</p>
</li>
<li>
<p><strong>Barreiras de Otimização</strong>: O compilador é forçado a assumir o pior cenário em termos de exceções, o que pode impedir otimizações importantes como:</p>
<ul>
<li>Inlining agressivo</li>
<li>Eliminação de código morto</li>
<li>Reordenação de instruções</li>
<li>Especulação de execução</li>
</ul>
</li>
<li>
<p><strong>Dificuldade de Análise Estática</strong>: Ferramentas de análise estática têm mais dificuldade em analisar corretamente o fluxo do programa quando exceções são usadas para controle de fluxo normal.</p>
</li>
<li>
<p><strong>Impacto no Tamanho do Binário</strong>: O código de tratamento de exceções adiciona tamanho significativo ao binário final, mesmo quando não está sendo usado.</p>
</li>
</ol>
<h3 id="exemplo-prático-benchmark-de-noexcept-vs-exceções">Exemplo Prático: Benchmark de <code>noexcept</code> vs Exceções</h3>
<p>Vamos ver um exemplo prático que demonstra a diferença de desempenho entre usar exceções para controle de fluxo versus usar <code>noexcept</code> com códigos de retorno:</p>


  <pre><code class="language-c">#include &lt;vector&gt;
#include &lt;chrono&gt;
#include &lt;iostream&gt;
#include &lt;stdexcept&gt;

// Versão que usa exceções para controle de fluxo
int processa_item_com_excecao(int valor) {
    if (valor &lt; 0) {
        throw std::invalid_argument(&#34;Valor negativo&#34;);
    }
    return valor * 2;
}

// Versão que usa códigos de retorno e é noexcept
bool processa_item_sem_excecao(int valor, int&amp; resultado) noexcept {
    if (valor &lt; 0) {
        return false;
    }
    resultado = valor * 2;
    return true;
}

// Função auxiliar para medir o tempo de execução
template&lt;typename Func&gt;
void medir_tempo(const std::string&amp; nome, Func funcao) {
    const int iteracoes = 1&#39;000&#39;000;
    auto inicio = std::chrono::high_resolution_clock::now();
    
    for (int i = -iteracoes/2; i &lt; iteracoes/2; &#43;&#43;i) {
        funcao(i);
    }
    
    auto fim = std::chrono::high_resolution_clock::now();
    auto duracao = std::chrono::duration_cast&lt;std::chrono::milliseconds&gt;(fim - inicio).count();
    
    std::cout &lt;&lt; nome &lt;&lt; &#34;: &#34; &lt;&lt; duracao &lt;&lt; &#34;ms\n&#34;;
}

int main() {
    // Teste com exceções
    medir_tempo(&#34;Com exceções&#34;, [](int i) {
        try {
            processa_item_com_excecao(i);
        } catch (const std::exception&amp;) {
            // Ignorar erros no benchmark
        }
    });
    
    // Teste sem exceções (usando códigos de retorno)
    medir_tempo(&#34;Sem exceções  &#34;, [](int i) {
        int resultado;
        processa_item_sem_excecao(i, resultado);
    });
    
    return 0;
}</code></pre>
 <p><strong>Resultados típicos em um compilador otimizado (g++ -O3):</strong></p>


  <pre><code class="language-">Com exceções: 45ms
Sem exceções: 2ms</code></pre>
 <p>Neste exemplo, a versão que usa exceções é aproximadamente <strong>22x mais lenta</strong> que a versão que usa códigos de retorno com <code>noexcept</code>. Isso ilustra claramente o custo de usar exceções para controle de fluxo em cenários de alto desempenho.</p>
<h3 id="quando-usar-noexcept">Quando Usar <code>noexcept</code></h3>
<ol>
<li>
<p><strong>Sempre que possível</strong>: Marque funções como <code>noexcept</code> quando você puder garantir que elas nunca lançarão exceções.</p>
</li>
<li>
<p><strong>Construtores e operadores de movimento</strong>: Especialmente importantes para permitir otimizações em contêineres.</p>
</li>
<li>
<p><strong>Destrutores</strong>: Devem sempre ser <code>noexcept</code> em C++11 e posteriores.</p>
</li>
<li>
<p><strong>Funções de baixo nível</strong>: Operações que são usadas em loops internos ou caminhos de código críticos para desempenho.</p>
</li>
</ol>
<h3 id="quando-não-usar-noexcept">Quando Não Usar <code>noexcept</code></h3>
<ol>
<li>
<p><strong>Quando a função pode lançar exceções</strong>: Nunca marque uma função como <code>noexcept</code> se ela pode lançar exceções.</p>
</li>
<li>
<p><strong>Em funções que chamam outras funções que podem lançar</strong>: A menos que você esteja capturando todas as exceções.</p>
</li>
<li>
<p><strong>Em APIs públicas</strong>: A menos que você tenha controle total sobre todas as exceções que podem ser lançadas.</p>
</li>
</ol>
<h3 id="impacto-no-tamanho-do-binário">Impacto no Tamanho do Binário</h3>
<p>Além do impacto no desempenho em tempo de execução, o uso de exceções também afeta o tamanho do binário gerado:</p>
<ul>
<li><strong>Código de Desempilhamento</strong>: O compilador precisa gerar tabelas de desenrolamento (unwind tables) para todas as funções que podem lançar exceções, mesmo que nunca sejam usadas.</li>
<li><strong>Informações de Tipo</strong>: Informações sobre os tipos de exceção que podem ser lançadas são armazenadas no binário.</li>
<li><strong>Rotinas de Suporte</strong>: O tempo de execução da linguagem inclui código para manipular exceções, mesmo que seu programa não as use.</li>
</ul>
<p>Em sistemas embarcados ou com restrições de memória, esse overhead pode ser significativo. Em um estudo de caso real, desativar o suporte a exceções em um projeto C++ médio pode reduzir o tamanho do binário em 10-20%.</p>
<h3 id="boas-práticas-com-noexcept">Boas Práticas com <code>noexcept</code></h3>
<ol>
<li><strong>Marque como <code>noexcept</code> funções que garantidamente não lançam exceções</strong>.</li>
<li><strong>Escreva operações de movimento como <code>noexcept</code></strong> sempre que possível.</li>
<li><strong>Evite exceções para fluxo lógico</strong> para permitir o uso eficiente de <code>noexcept</code>.</li>
<li><strong>Documente claramente</strong> quando uma função não é <code>noexcept</code> e por quê.</li>
</ol>
<p>A biblioteca padrão do C++ é um ótimo exemplo: funções como <code>std::move_if_noexcept</code> mostram como o design da linguagem incentiva o uso correto de <code>noexcept</code> para obter o máximo desempenho.</p>
<h3 id="benchmark-exceções-vs-ifelse">Benchmark: Exceções vs If/Else</h3>
<p>Vamos comparar o desempenho entre usar exceções e verificações condicionais com um exemplo prático. O código a seguir testa as duas abordagens:</p>


  <pre><code class="language-c">#include &lt;chrono&gt;
#include &lt;iostream&gt;
#include &lt;stdexcept&gt;
#include &lt;vector&gt;

// Abordagem com exceções
int dividirComExcecao(int a, int b) {
    if (b == 0) {
        throw std::runtime_error(&#34;Divisão por zero&#34;);
    }
    return a / b;
}

// Abordagem com verificação condicional
bool dividirComIf(int a, int b, int&amp; resultado) {
    if (b == 0) {
        return false; // Indica falha
    }
    resultado = a / b;
    return true; // Indica sucesso
}

int main() {
    const int NUM_ITERACOES = 1&#39;000&#39;000;
    int resultado;
    
    // Teste com exceções
    auto inicio = std::chrono::high_resolution_clock::now();
    for (int i = 0; i &lt; NUM_ITERACOES; &#43;&#43;i) {
        try {
            resultado = dividirComExcecao(10, (i % 10) ? 2 : 0);
        } catch (const std::exception&amp;) {
            // Tratamento da exceção
        }
    }
    auto fim = std::chrono::high_resolution_clock::now();
    auto duracao_excecoes = std::chrono::duration_cast&lt;std::chrono::microseconds&gt;(fim - inicio).count();

    // Teste com if/else
    inicio = std::chrono::high_resolution_clock::now();
    for (int i = 0; i &lt; NUM_ITERACOES; &#43;&#43;i) {
        if (!dividirComIf(10, (i % 10) ? 2 : 0, resultado)) {
            // Tratamento do erro
        }
    }
    fim = std::chrono::high_resolution_clock::now();
    auto duracao_if = std::chrono::duration_cast&lt;std::chrono::microseconds&gt;(fim - inicio).count();

    std::cout &lt;&lt; &#34;Tempo com exceções: &#34; &lt;&lt; duracao_excecoes &lt;&lt; &#34; microssegundos\n&#34;;
    std::cout &lt;&lt; &#34;Tempo com if/else: &#34; &lt;&lt; duracao_if &lt;&lt; &#34; microssegundos\n&#34;;
    std::cout &lt;&lt; &#34;Razão: ~&#34; &lt;&lt; (duracao_excecoes / (double)duracao_if) &lt;&lt; &#34;x mais lento\n&#34;;

    return 0;
}</code></pre>
 <p><strong>Resultados típicos em um sistema moderno (pode variar por compilador/plataforma):</strong></p>
<ul>
<li><strong>Com exceções:</strong> ~50,000-100,000 microssegundos</li>
<li><strong>Com if/else:</strong> ~500-1,000 microssegundos</li>
<li><strong>Diferença:</strong> As exceções podem ser <strong>50-200x mais lentas</strong> quando lançadas frequentemente</li>
</ul>
<p>Pense assim: usar exceções para controle de fluxo é como chamar os bombeiros para apagar um fósforo. Funciona, mas é um exagero para problemas pequenos e previsíveis! Veja o diagrama abaixo:</p>


  
  <div class="mermaid">graph TD
    A[&#34;Inicio da Execucao&#34;] --&gt; B{&#34;Excecao Lancada (throw)&#34;}
    B --&gt; C[&#34;Criacao/Copia do Objeto de Excecao&lt;br/&gt;Custo: Variavel depende do objeto&#34;]
    C --&gt; D[&#34;Inicio do Desempilhamento da Pilha&lt;br/&gt;Custo: Depende do numero e complexidade dos destrutores&#34;]
    D --&gt; E[&#34;Busca por Bloco catch Adequado&lt;br/&gt;Custo: Depende da profundidade da pilha e da implementacao&#34;]
    E --&gt; F[&#34;Execucao do Manipulador catch&#34;]
    F --&gt; G[&#34;Continuacao ou Termino&#34;]

    subgraph &#34;Overhead Significativo Quando Excecao Ocorre&#34;
        direction LR
        C
        D
        E
    end

    style D fill:#ff9999,stroke:#ff0000
    style E fill:#ffcccc,stroke:#ff0000
    style C fill:#ffe6e6,stroke:#ff0000</div>
 <p>Este diagrama mostra o que acontece quando uma exceção é lançada em C++. A parte mais pesada é quando o programa &ldquo;volta no tempo&rdquo; (D), chamando todos os destrutores, e quando ele precisa procurar qual bloco <code>catch</code> vai resolver o problema (E). É como se o computador tivesse que desarmar uma bomba enquanto corre uma maratona! Abaixo está um exemplo de como isso pode afetar o desempenho de um loop:</p>


  
  <div class="mermaid">graph TD
    A[&#34;Início do Loop&#34;] --&gt; B[&#34;Iteração&#34;]
    B --&gt;|&#34;Condição de &#39;erro&#39; previsível&#34;| C{&#34;Uso de Exceção para Fluxo&#34;}
    C --&gt;|&#34;throw&#34;| D1[&#34;Criação Objeto Exceção&#34;]
    D1 --&gt; D2[&#34;Desempilhamento &#43; Busca `catch`&#34;]
    D2 --&gt; E[&#34;Tratamento no `catch` e Próxima Iteração&#34;]
    B --&gt;|&#34;Condição normal&#34;| E
    E --&gt;|&#34;Mais Iterações&#34;| B
    E --&gt; F[&#34;Fim do Loop&#34;]

    style D2 fill:#ff9999,stroke:#ff0000
    style D1 fill:#ffe6e6,stroke:#ff0000</div>
 <p>Este diagrama mostra como o desempenho piora quando usamos exceções em loops. Cada vez que um <code>throw</code> acontece, o programa precisa fazer todo aquele trabalho pesado de desempilhar a pilha e procurar o <code>catch</code> certo. Isso é MUITO mais lento que um simples <code>if</code>. É como comparar andar de bicicleta (verificação condicional) com ter que parar, desmontar e remontar a bicicleta (exceção) a cada quarteirão! Por exemplo, se você tem um loop que roda 10 milhões de vezes e em cada iteração pode lançar uma exceção, o custo de desempilhar a pilha e procurar o <code>catch</code> pode ser substancialmente mais lento do que uma simples verificação condicional. O diagrama abaixo mostra como isso pode afetar o desempenho:</p>


  
  <div class="mermaid">graph TD
    A[&#34;Comparação de Performance Relativa em C&#43;&#43;&#34;] --&gt; B[&#34;Verificação Condicional (if/else, std::optional check)&lt;br/&gt;Custo: Muito Baixo (poucos ciclos de CPU)&#34;]
    A --&gt; C[&#34;Exceção Lançada e Capturada&lt;br/&gt;Custo: Significativamente Mais Alto&lt;br/&gt;(Pode ser 100x-1000x&#43; mais lento que um if)&#34;]

    style B fill:#99ff99,stroke:#00ff00
    style C fill:#ffcccc,stroke:#ff0000

    B --&gt; E[&#34;Preferível para fluxo lógico e erros esperados&#34;]
    C --&gt; F[&#34;Reservado para condições verdadeiramente excepcionais e inesperadas&#34;]</div>
 <p>Este diagrama compara os custos. A diferença de velocidade é gigante em código que precisa ser rápido, como loops importantes, processamento de muitos dados ou sistemas que não podem atrasar. No mundo C++, principalmente em áreas como jogos, dispositivos com poucos recursos ou sistemas financeiros de alta velocidade, lançar exceções custa caro! Por isso, muitas equipes simplesmente proíbem exceções nesses tipos de projeto.</p>
<hr>
<h2 id="quando-usar-trycatch-os-casos-de-uso-apropriados">Quando Usar Try/Catch? Os Casos de Uso Apropriados</h2>
<p>Apesar das desvantagens de desempenho e dos problemas de design discutidos, o <code>try/catch</code> tem seu lugar em situações específicas onde seu uso é justificado:</p>
<h3 id="1-falhas-de-sistema-e-recursos-externos">1. <strong>Falhas de Sistema e Recursos Externos</strong></h3>
<ul>
<li><strong>Conexões de rede</strong>: Quando uma conexão falha inesperadamente</li>
<li><strong>Operações de E/S</strong>: Falhas ao ler/escrever arquivos ou dispositivos</li>
<li><strong>Alocação de memória</strong>: Quando <code>new</code> falha (embora raro em sistemas modernos)</li>
</ul>


  <pre><code class="language-c">try {
    auto* buffer = new char[LARGE_BUFFER_SIZE];
    // Usar buffer...
    delete[] buffer;
} catch (const std::bad_alloc&amp; e) {
    // Tratar falha de alocação
}</code></pre>
 <h3 id="2-validação-de-entrada-em-apis-públicas">2. <strong>Validação de Entrada em APIs Públicas</strong></h3>
<ul>
<li>Em bibliotecas onde você não controla como os usuários vão chamar suas funções</li>
<li>Quando a validação de parâmetros é complexa e espalhada pela função</li>
</ul>


  <pre><code class="language-c">class Database {
public:
    void connect(const std::string&amp; connectionString) {
        if (connectionString.empty()) {
            throw std::invalid_argument(&#34;Connection string cannot be empty&#34;);
        }
        // Tentar conexão...
    }
};</code></pre>
 <h3 id="3-recuperação-de-estados-inconsistentes">3. Recuperação de Estados Inconsistentes</h3>
<p>Em sistemas onde múltiplas operações precisam ser tratadas como uma única unidade atômica, o <code>try/catch</code> é essencial para garantir a consistência dos dados. Este é particularmente importante em operações críticas onde falhas parciais podem levar a estados inconsistentes.</p>
<h4 id="casos-de-uso-típicos">Casos de Uso Típicos:</h4>
<ul>
<li><strong>Sistemas transacionais</strong>: Bancos de dados, sistemas financeiros</li>
<li><strong>Atualizações em lote</strong>: Quando múltiplas entidades precisam ser atualizadas atomicamente</li>
<li><strong>Operações de rollback</strong>: Quando uma falha requer desfazer alterações parciais</li>
</ul>


  <pre><code class="language-c">class SistemaBancario {
    std::vector&lt;Transacao&gt; transacoesPendentes_;
    
public:
    void transferir(Conta&amp; origem, Conta&amp; destino, double valor) {
        // Inicia uma transação lógica
        auto transacao = iniciarTransacao();
        
        try {
            // Tenta executar as operações atômicas
            origem.debitar(valor);
            
            // Simula uma falha inesperada
            if (rand() % 100 &lt; 5) { // 5% de chance de falha
                throw std::runtime_error(&#34;Falha na rede durante transferência&#34;);
            }
            
            destino.creditar(valor);
            
            // Registra a transação bem-sucedida
            registrarTransacao(transacao, origem, destino, valor);
            
        } catch (const std::exception&amp; e) {
            // Em caso de falha, desfaz as operações realizadas
            reverterTransacao(transacao);
            
            // Registra a falha para auditoria
            registrarFalha(transacao, e);
            
            // Propaga a exceção para o chamador
            throw TransacaoFalhouException(&#34;Falha na transferência&#34;, e);
        }
    }
    
private:
    // Métodos auxiliares para gerenciamento de transações
    Transacao iniciarTransacao() {
        // Implementação para iniciar uma nova transação
        return Transacao{/* ... */};
    }
    
    void registrarTransacao(const Transacao&amp;, const Conta&amp;, const Conta&amp;, double) {
        // Implementação para registrar transação bem-sucedida
    }
    
    void reverterTransacao(const Transacao&amp;) {
        // Implementação para reverter uma transação
    }
    
    void registrarFalha(const Transacao&amp;, const std::exception&amp;) {
        // Implementação para registrar falhas
    }
};</code></pre>
 <h4 id="vantagens-desta-abordagem">Vantagens Desta Abordagem:</h4>
<ol>
<li><strong>Atomicidade</strong>: Garante que todas as operações sejam concluídas com sucesso, ou nenhuma delas seja aplicada</li>
<li><strong>Consistência</strong>: Mantém o sistema em um estado consistente mesmo após falhas</li>
<li><strong>Rastreabilidade</strong>: Permite rastrear e auditar operações bem-sucedidas e falhas</li>
<li><strong>Segurança</strong>: Protege contra corrupção de dados em cenários de falha</li>
</ol>
<h4 id="boas-práticas">Boas Práticas:</h4>
<ul>
<li>Sempre reverta as alterações na ordem inversa em que foram feitas</li>
<li>Documente claramente quais operações são atômicas</li>
<li>Considere usar o padrão Command para operações complexas que precisam ser desfeitas</li>
<li>Registre falhas de forma detalhada para facilitar a depuração</li>
</ul>
<h3 id="4-em-ambientes-de-alto-nível">4. Em Ambientes de Alto Nível</h3>
<p>Em certos contextos, a clareza e a manutenibilidade do código podem ser priorizadas em relação ao desempenho bruto. Nestes casos, o uso de exceções pode ser mais apropriado.</p>
<h4 id="cenários-adequados">Cenários Adequados:</h4>
<ol>
<li>
<p><strong>Aplicações de Negócios</strong></p>
<ul>
<li>Sistemas com lógica complexa de negócios</li>
<li>Aplicações onde o tempo de desenvolvimento é crítico</li>
<li>Código que será mantido por uma equipe diversificada</li>
</ul>
</li>
<li>
<p><strong>Scripts e Ferramentas</strong></p>
<ul>
<li>Scripts de automação</li>
<li>Ferramentas de linha de comando</li>
<li>Protótipos e provas de conceito</li>
</ul>
</li>
<li>
<p><strong>APIs de Alto Nível</strong></p>
<ul>
<li>Frameworks de aplicação</li>
<li>Bibliotecas de domínio específico</li>
<li>Camadas de apresentação</li>
</ul>
</li>
</ol>
<h4 id="exemplo-api-de-processamento-de-pedidos">Exemplo: API de Processamento de Pedidos</h4>


  <pre><code class="language-c">class ProcessadorPedidos {
public:
    struct DadosPedido {
        std::string clienteId;
        std::vector&lt;std::string&gt; itens;
        std::string enderecoEntrega;
        std::string metodoPagamento;
    };

    void processarPedido(const DadosPedido&amp; pedido) {
        try {
            validarPedido(pedido);
            
            auto pagamento = processarPagamento(pedido);
            
            auto pedidoCriado = criarPedidoNoSistema(pedido, pagamento);
            
            notificarCliente(pedidoCriado);
            
        } catch (const ErroValidacao&amp; e) {
            // Erros de validação são esperados e tratados de forma amigável
            registrarAviso(&#34;Validação falhou&#34;, e);
            throw;
            
        } catch (const ErroPagamento&amp; e) {
            // Erros de pagamento requerem atenção especial
            notificarTimeFinanceiro(e);
            throw;
            
        } catch (const std::exception&amp; e) {
            // Erros inesperados são registrados e propagados
            registrarErro(&#34;Falha inesperada ao processar pedido&#34;, e);
            throw ErroProcessamentoPedido(&#34;Não foi possível processar o pedido&#34;, e);
        }
    }

private:
    void validarPedido(const DadosPedido&amp;) {
        // Validação detalhada do pedido
    }
    
    Pagamento processarPagamento(const DadosPedido&amp;) {
        // Lógica de processamento de pagamento
        return Pagamento{};
    }
    
    Pedido criarPedidoNoSistema(const DadosPedido&amp;, const Pagamento&amp;) {
        // Criação do pedido no banco de dados
        return Pedido{};
    }
    
    void notificarCliente(const Pedido&amp;) {
        // Envio de confirmação por e-mail/SMS
    }
    
    // Métodos auxiliares
    void registrarAviso(const std::string&amp;, const std::exception&amp;) {}
    void notificarTimeFinanceiro(const ErroPagamento&amp;) {}
    void registrarErro(const std::string&amp;, const std::exception&amp;) {}
};</code></pre>
 <h3 id="regra-de-ouro-para-uso-de-exceções">Regra de Ouro para Uso de Exceções</h3>
<p>Use exceções de forma estratégica, considerando as seguintes diretrizes:</p>
<h4 id="use-exceções-para">Use Exceções Para:</h4>
<ul>
<li><strong>Condições excepcionais</strong> que quebram o fluxo normal de execução</li>
<li><strong>Erros que não podem ser tratados localmente</strong> e precisam ser propagados</li>
<li><strong>Falhas em recursos externos</strong> (banco de dados, rede, sistema de arquivos)</li>
<li><strong>Violações de pré-condições</strong> em APIs públicas</li>
</ul>
<h4 id="evite-exceções-para">Evite Exceções Para:</h4>
<ul>
<li><strong>Controle de fluxo</strong> normal do programa</li>
<li><strong>Validação de entrada do usuário</strong> (use validação explícita)</li>
<li><strong>Cenários esperados</strong> que fazem parte da lógica de negócios</li>
<li><strong>Em loops de alto desempenho</strong> onde o custo das exceções é proibitivo</li>
</ul>
<h4 id="alternativas-para-cenários-de-erro-comum">Alternativas para Cenários de Erro Comum:</h4>
<ol>
<li>
<p><strong><code>std::optional&lt;T&gt;</code></strong> - Para valores opcionais</p>


  <pre><code class="language-c">std::optional&lt;Usuario&gt; buscarUsuario(int id);</code></pre>
 </li>
<li>
<p><strong><code>std::expected&lt;T, E&gt;</code> (C++23+)</strong> - Para operações que podem falhar</p>


  <pre><code class="language-c">std::expected&lt;Arquivo, ErroIO&gt; abrirArquivo(const std::string&amp; caminho);</code></pre>
 </li>
<li>
<p><strong>Tipos de união</strong> - Para múltiplos resultados possíveis</p>


  <pre><code class="language-c">std::variant&lt;Sucesso, ErroValidacao, ErroConexao&gt; enviarDados(const Dados&amp;);</code></pre>
 </li>
<li>
<p><strong>Códigos de status</strong> - Para APIs de baixo nível</p>


  <pre><code class="language-c">enum class Status {
    Ok,
    Falha,
    NaoEncontrado,
    SemPermissao
};

Status salvarDados(const Dados&amp;, std::string* mensagemErro = nullptr);</code></pre>
 </li>
</ol>
<p>Ao escolher entre exceções e códigos de erro, considere:</p>
<ul>
<li>A frequência esperada da condição de erro</li>
<li>O impacto no desempenho</li>
<li>A clareza e manutenibilidade do código</li>
<li>As convenções da base de código existente</li>
<li>As expectativas dos desenvolvedores que usarão sua API</li>
</ul>
<hr>
<p>Eles preferem usar alternativas como códigos de erro, <code>std::optional</code>, <code>std::variant</code> (com um tipo de erro) ou <code>std::expected</code> (novidade do C++23). Essas opções lidam com erros de um jeito mais rápido e previsível. Usar exceções para controlar o fluxo normal nesses casos é como usar uma escavadeira para plantar uma florzinha - um exagero que vai deixar seu programa muito mais lento!</p>
<hr>
<h3 id="4-tipagem-fraca-e-má-prática-de-design">4. Tipagem Fraca e Má Prática de Design</h3>
<p>Em TypeScript, quando usamos um bloco <code>catch</code>, o erro geralmente vem como <code>any</code> ou <code>unknown</code> (sendo <code>unknown</code> o padrão desde o TS 4.4 e a opção mais segura). O problema? Mesmo quando fazemos verificações de tipo dentro do <code>catch</code>, nossa função não mostra claramente quais erros podem acontecer. É como se a função escondesse seus problemas!</p>
<p>Diferente disso, quando usamos abordagens como <code>Either</code> ou <code>Result</code>, todos os possíveis erros ficam declarados na assinatura da função - assim qualquer pessoa consegue ver o que pode dar errado sem precisar ler o código todo. O código abaixo mostra como isso pode ser feito:</p>


  <pre><code class="language-typescript">try {
  // Alguma operação
} catch (error: unknown) {
  if (error instanceof SyntaxError) {
    console.error(&#34;Erro de sintaxe:&#34;, error.message);
  } else if (error instanceof Error) {
    console.error(&#34;Erro genérico:&#34;, error.message);
  } else {
    console.error(&#34;Erro inesperado:&#34;, error);
  }
}</code></pre>
 <h4 id="o-problema-de-usar-trycatch-para-fluxo-de-controle">O Problema de Usar Try/Catch para Fluxo de Controle</h4>
<p><strong>O <code>try/catch</code> foi feito para erros inesperados</strong>, aquelas situações excepcionais que quebram o fluxo normal do programa. Coisas como falhas de rede inesperadas, arquivos corrompidos ou erros de permissão - situações que você não espera que aconteçam durante o fluxo normal de execução.</p>
<p>No entanto, um padrão comum (e problemático) é usar <code>try/catch</code> para controlar o fluxo lógico do programa. Vamos entender por que isso é considerado uma má prática de design através de um exemplo concreto:</p>
<p>Imagina que você tá programando e sabe que, às vezes, as coisas podem dar errado. Tipo, você pede pra um sistema buscar um arquivo, mas o arquivo não existe. Ou tenta se conectar num servidor, mas a internet caiu. Pra essas &ldquo;zicas&rdquo; inesperadas, a gente tem uma ferramenta chamada <code>try/catch</code>. O <code>try</code> é onde você &ldquo;tenta&rdquo; fazer alguma coisa que pode dar pau, e o <code>catch</code> é o &ldquo;plano B&rdquo;, o que fazer se o pau acontecer.</p>
<p>Agora, pensa no <code>try/catch</code> como o alarme de incêndio da sua casa. Você não ativa o alarme toda vez que vai cozinhar, só porque <em>pode</em> ter fumaça, né? Ele é pra emergências de verdade, pra quando o fogo já começou e você não esperava por isso. Usar o <code>try/catch</code> pra tudo é como disparar o alarme de incêndio só pra avisar que o pão queimou um pouquinho na torradeira. É um exagero!</p>
<p>O problema que o texto aponta é quando a galera usa o <code>try/catch</code> pra coisas que são, na verdade, parte do fluxo normal do programa. Tipo, verificar se um usuário digitou o nome ou se um preço existe. São coisas que a gente <em>espera</em> que possam acontecer, não são desastres inesperados. É como se você usasse o &ldquo;plano B&rdquo; pra situações que deveriam ser tratadas com um simples &ldquo;se isso, então aquilo&rdquo;.</p>
<p>Fazer isso é considerado uma &ldquo;má prática de design&rdquo; porque, além de poder deixar o código mais lento, ele fica mais confuso de ler. É como usar um martelo pra apertar um parafuso: funciona, mas não é a ferramenta ideal e pode estragar as coisas. A ideia é manter o código limpo, fácil de entender e usando as ferramentas certas para cada tarefa.</p>
<hr>
<h2 id="má-prática-de-design">Má Prática de Design</h2>
<p><strong>O <code>try/catch</code> foi feito pra pegar ERROS INESPERADOS, aquelas surpresas desagradáveis que quebram seu programa.</strong> Tipo, o banco de dados ficou offline do nada, ou um arquivo essencial sumiu. Coisas que não deveriam acontecer, mas acontecem.</p>
<p>Quando você usa <code>try/catch</code> pra coisas que você JÁ ESPERA que possam acontecer (tipo, um usuário não digitou o preço de um produto, ou um campo veio vazio), você tá usando a ferramenta errada. Pra essas situações previsíveis, a gente deve usar um <code>if</code> simples, ou outras formas mais diretas de checar e lidar com a situação.</p>
<p><strong>Vamos ver o exemplo ruim (o anti-padrão):</strong></p>


  <pre><code class="language-typescript">// Jeito ERRADO: Usando exceção pra controlar o fluxo normal
function getItemPrice(item: { name: string; price?: number }): number {
  try {
    // Tenta fazer isso...
    if (item.price === undefined) {
      // Se o preço não foi definido (algo que PODE acontecer)...
      throw new Error(&#34;Preço não definido&#34;); // ...ele FORÇA um ERRO! É como gritar &#34;PROBLEMA!&#34;
    }
    return item.price; // Se tinha preço, retorna o preço
  } catch (error) {
    // Se &#34;deu o erro&#34; que a gente mesmo forçou...
    return 0; // ...retorna 0 como preço padrão.
  }
}</code></pre>
 <p><strong>Por que isso é ruim?</strong></p>
<ol>
<li><strong>Confuso:</strong> Você olha e pensa que tá tratando um erro grave, mas na verdade é só uma verificação normal se o preço existe ou não.</li>
<li><strong>Menos eficiente:</strong> Lançar e capturar exceções é um processo mais &ldquo;caro&rdquo; (lento) pro computador do que um simples <code>if</code>.</li>
<li><strong>Não é a intenção:</strong> Exceções são para quebrar o fluxo normal por causa de um problema sério, não para guiar o fluxo normal.</li>
</ol>
<p><strong>Agora, o jeito CERTO e mais esperto:</strong></p>


  <pre><code class="language-typescript">function getItemPrice(item: { name: string; price?: number }): number {
  // Se item.price existir (não for undefined nem null), usa ele.
  // Senão (??), usa 0.
  return item.price ?? 0;
}</code></pre>
 <p><strong>Por que isso é bom?</strong></p>
<ol>
<li><strong>Claro como água:</strong> Bateu o olho, entendeu. Se tem preço, usa o preço. Se não tem, usa 0. Sem drama.</li>
<li><strong>Direto ao ponto:</strong> Resolve o problema com uma linha simples e lógica.</li>
<li><strong>Mais eficiente:</strong> É uma verificação direta, muito mais rápida pro sistema.</li>
</ol>
<p>Guarde o <code>try/catch</code> (o &ldquo;alarme de incêndio&rdquo;) para quando a coisa feder de verdade, pra erros que você não estava esperando. Para as coisas do dia a dia, como verificar se um valor existe ou não, use as ferramentas mais simples e diretas, como um <code>if</code> ou operadores como o <code>??</code> (nullish coalescing). Seu código fica mais limpo, mais rápido e mais fácil de dar manutenção!</p>
<hr>
<h3 id="abordagens-em-outras-linguagens">Abordagens em Outras Linguagens</h3>
<p>Muitas linguagens modernas ou com filosofias diferentes de tratamento de erro evitam o uso de exceções para erros recuperáveis, favorecendo valores de retorno explícitos. Isso torna o fluxo de controle mais claro e os possíveis erros parte do contrato da função. Vamos ver como essas abordagens podem inspirar práticas em JavaScript/TypeScript.</p>
<h4 id="rust-uma-abordagem-moderna-para-tratamento-de-erros"><strong>Rust: Uma Abordagem Moderna para Tratamento de Erros</strong></h4>
<p>Rust adota uma abordagem única e poderosa para o tratamento de erros que elimina completamente a necessidade de exceções tradicionais. O sistema de tipos de Rust garante que todos os erros sejam tratados explicitamente, tornando os programas mais seguros e previsíveis.</p>
<h5 id="os-pilares-do-tratamento-de-erros-em-rust">Os Pilares do Tratamento de Erros em Rust</h5>
<ol>
<li>
<p><strong><code>Option&lt;T&gt;</code> para Valores Opcionais</strong></p>
<ul>
<li><code>Some(value)</code>: Indica a presença de um valor</li>
<li><code>None</code>: Indica a ausência de um valor</li>
<li>Elimina o problema do <code>null</code>/<code>undefined</code> presente em outras linguagens</li>
</ul>
</li>
<li>
<p><strong><code>Result&lt;T, E&gt;</code> para Operações que Podem Falhar</strong></p>
<ul>
<li><code>Ok(value)</code>: Indica sucesso, contendo o valor resultante</li>
<li><code>Err(error)</code>: Indica falha, contendo informações sobre o erro</li>
<li>Força o tratamento explícito de erros em tempo de compilação</li>
</ul>
</li>
<li>
<p><strong>O Operador <code>?</code> para Propagação Concisas</strong></p>
<ul>
<li>Propaga erros automaticamente</li>
<li>Mantém o código limpo e legível</li>
<li>Funciona tanto com <code>Option</code> quanto com <code>Result</code></li>
</ul>
</li>
</ol>
<h5 id="exemplo-prático-leitura-de-arquivo">Exemplo Prático: Leitura de Arquivo</h5>


  <pre><code class="language-rust">use std::fs::File;
use std::io::{self, Read};

// Função que pode falhar ao ler um arquivo
fn ler_arquivo(caminho: &amp;str) -&gt; Result&lt;String, io::Error&gt; {
    let mut arquivo = File::open(caminho)?;
    let mut conteudo = String::new();
    arquivo.read_to_string(&amp;mut conteudo)?;
    Ok(conteudo)
}

// Uso com tratamento de erro explícito
fn processar_arquivo(caminho: &amp;str) -&gt; Result&lt;usize, String&gt; {
    let conteudo = ler_arquivo(caminho)
        .map_err(|e| format!(&#34;Falha ao ler o arquivo: {}&#34;, e))?;
    
    // Processamento do conteúdo aqui
    let contagem = conteudo.lines().count();
    Ok(contagem)
}

// Função principal
fn main() {
    match processar_arquivo(&#34;dados.txt&#34;) {
        Ok(linhas) =&gt; println!(&#34;Arquivo processado com {} linhas&#34;, linhas),
        Err(erro) =&gt; eprintln!(&#34;Erro: {}&#34;, erro),
    }
}</code></pre>
 <h5 id="vantagens-da-abordagem-de-rust">Vantagens da Abordagem de Rust</h5>
<ol>
<li>
<p><strong>Segurança de Tipos</strong></p>
<ul>
<li>O compilador garante que todos os casos de erro são tratados</li>
<li>Impossível esquecer de verificar um erro</li>
<li>Sem surpresas em tempo de execução</li>
</ul>
</li>
<li>
<p><strong>Performance</strong></p>
<ul>
<li>Sem custo de desenrolamento de pilha (stack unwinding)</li>
<li><code>Result</code> e <code>Option</code> são otimizados para ter custo zero quando não usados</li>
<li>O compilador otimiza o código para ser tão eficiente quanto códigos de erro manuais</li>
</ul>
</li>
<li>
<p><strong>Clareza</strong></p>
<ul>
<li>As assinaturas das funções documentam explicitamente os possíveis erros</li>
<li>Fácil de rastrear a origem dos erros</li>
<li>O fluxo de controle é explícito e previsível</li>
</ul>
</li>
</ol>
<h5 id="erros-irrecuperáveis-com-panic">Erros Irrecuperáveis com <code>panic!</code></h5>
<p>Rust reserva o <code>panic!</code> para situações verdadeiramente excepcionais onde o programa não pode continuar de forma segura:</p>


  <pre><code class="language-rust">fn dividir(a: f64, b: f64) -&gt; f64 {
    if b == 0.0 {
        panic!(&#34;Divisão por zero não é permitida&#34;);
    }
    a / b
}</code></pre>
 <h5 id="boas-práticas-em-rust">Boas Práticas em Rust</h5>
<ol>
<li>
<p><strong>Use <code>Result</code> para erros recuperáveis</strong></p>
<ul>
<li>Erros de validação</li>
<li>Falhas de I/O</li>
<li>Problemas de rede</li>
</ul>
</li>
<li>
<p><strong>Use <code>Option</code> para valores opcionais</strong></p>
<ul>
<li>Buscas que podem não retornar resultado</li>
<li>Configurações opcionais</li>
<li>Valores que podem ser nulos</li>
</ul>
</li>
<li>
<p><strong>Reserve <code>panic!</code> para erros irrecuperáveis</strong></p>
<ul>
<li>Bugs do programa</li>
<li>Invariantes quebradas</li>
<li>Condições que indicam um bug no código</li>
</ul>
</li>
</ol>
<p><strong>Inspiração para JavaScript/TypeScript</strong>:
A biblioteca <code>fp-ts</code> traz conceitos similares ao JavaScript/TypeScript, permitindo um estilo de programação mais seguro e expressivo:</p>


  <pre><code class="language-typescript">import { Either, left, right, isLeft } from &#34;fp-ts/Either&#34;;
import { pipe } from &#34;fp-ts/function&#34;;

// Similar ao Result do Rust
function parseNumber(s: string): Either&lt;string, number&gt; {
    const result = parseInt(s);
    return isNaN(result) ? 
        left(&#34;Número inválido&#34;) : 
        right(result);
}

// Uso com pipe (similar ao operador ? do Rust)
const result = pipe(
    &#34;123&#34;,
    parseNumber,
    Either.map(n =&gt; n * 2),
    Either.getOrElse(() =&gt; 0)
);

// Tratamento de erros explícito
if (isLeft(result)) {
    console.error(&#34;Erro:&#34;, result.left);
} else {
    console.log(&#34;Resultado:&#34;, result.right);
}</code></pre>
 <p>Esta abordagem inspirada em Rust torna o código mais previsível e fácil de manter, eliminando muitos dos problemas associados ao uso inadequado de <code>try/catch</code> para controle de fluxo.</p>
<h4 id="clojure-uma-abordagem-funcional-para-tratamento-de-erros"><strong>Clojure: Uma Abordagem Funcional para Tratamento de Erros</strong></h4>
<p>Clojure, uma linguagem funcional moderna que roda na JVM, oferece uma perspectiva única sobre o tratamento de erros que se alinha perfeitamente com seus princípios de programação funcional. Como destacado por Daniel Higginbotham em &ldquo;Clojure for the Brave and True&rdquo;, a linguagem privilegia a simplicidade e a imutabilidade, resultando em abordagens mais elegantes para lidar com erros.</p>
<h5 id="imutabilidade-e-funções-puras">Imutabilidade e Funções Puras</h5>
<p>No coração da filosofia do Clojure está o conceito de imutabilidade e funções puras (Capítulo 5). Isso significa que:</p>
<ol>
<li><strong>Sem Efeitos Colaterais</strong>: Funções em Clojure são projetadas para não ter efeitos colaterais, tornando o comportamento do código mais previsível.</li>
<li><strong>Transparência Referencial</strong>: Dada a mesma entrada, uma função pura sempre retornará a mesma saída, facilitando o raciocínio sobre o código.</li>
<li><strong>Valores Imutáveis</strong>: Dados em Clojure são imutáveis por padrão, eliminando uma classe inteira de bugs relacionados a estado compartilhado.</li>
</ol>
<p>Esses princípios levam naturalmente a um estilo de programação onde erros são tratados como valores que fluem pelo sistema, em vez de serem tratados como fluxo de controle excepcional.</p>
<h5 id="interoperabilidade-com-a-jvm-e-exceções-java">Interoperabilidade com a JVM e Exceções Java</h5>
<p>Como Clojure roda na JVM (Capítulo 12), ele oferece suporte completo à interoperabilidade com Java, incluindo o tratamento de exceções. No entanto, a abordagem idiomática do Clojure é usar exceções apenas para situações verdadeiramente excepcionais ou para interoperabilidade com bibliotecas Java:</p>


  <pre><code class="language-clojure">;; Exemplo de tratamento de exceção Java em Clojure
(try
  (let [file (java.io.File. &#34;/caminho/inexistente&#34;)]
    (when-not (.exists file)
      (throw (java.io.FileNotFoundException. &#34;Arquivo não encontrado&#34;)))
    (slurp file))
  (catch java.io.FileNotFoundException e
    (println &#34;Erro ao processar arquivo:&#34; (.getMessage e))
    nil)  ; Retorna nil em caso de erro
  (finally
    (println &#34;Operação de arquivo concluída&#34;)))</code></pre>
 <p><strong>Quando usar try/catch em Clojure:</strong></p>
<ul>
<li>Ao chamar código Java que pode lançar exceções verificadas</li>
<li>Para erros verdadeiramente excepcionais que indicam falhas irrecuperáveis</li>
<li>Quando a interoperabilidade com código Java exige o uso de exceções</li>
</ul>
<h5 id="gerenciamento-de-estado-e-concorrência">Gerenciamento de Estado e Concorrência</h5>
<p>Os Capítulos 9-11 de &ldquo;<a href="https://www.braveclojure.com/">Clojure for the Brave and True</a>&rdquo;) abordam o modelo de estado e concorrência do Clojure, que influencia profundamente como os erros são tratados em ambientes concorrentes:</p>
<ol>
<li>
<p><strong>Atoms e Refs</strong> (Capítulo 10):</p>


  <pre><code class="language-clojure">;; Atom para estado compartilhado seguro
(def contador (atom 0))

(defn incrementar-contador! []
  (try
    (swap! contador inc)
    (catch Exception e
      (println &#34;Erro ao incrementar contador:&#34; e)
      @contador)))  ; Retorna o valor atual em caso de erro</code></pre>
 </li>
<li>
<p><strong>core.async para Concorrência</strong> (Capítulo 11):</p>


  <pre><code class="language-clojure">(require &#39;[clojure.core.async :as async :refer [go &lt;! &gt;!]])

(defn processar-assincrono [dados]
  (go
    (try
      (let [resultado (processar-dados dados)]
        (if (:erro resultado)
          (throw (Exception. (:mensagem-err resultado)))
          resultado))
      (catch Exception e
        {:erro true :mensagem (str &#34;Falha no processamento: &#34; (.getMessage e))}))))</code></pre>
 </li>
</ol>
<h5 id="macros-para-tratamento-de-erros-personalizado">Macros para Tratamento de Erros Personalizado</h5>
<p>Os Capítulos 7-8 abordam macros em Clojure, que podem ser usadas para criar construtores de tratamento de erro mais expressivos:</p>


  <pre><code class="language-clojure">;; Exemplo de macro para tratamento de erros com backoff exponencial
(defmacro with-retry [max-retries &amp; body]
  `(loop [retries# ~max-retries]
     (let [result# (try
                     {:success? true :result (do ~@body)}
                     (catch Exception e#
                       (if (pos? retries#)
                         (do
                           (Thread/sleep (* 1000 (- ~max-retries retries#)))
                           {:success? false :retry? true})
                         {:success? false :error e#}))))]
       (cond
         (:success? result#) (:result result#)
         (:retry? result#) (recur (dec retries#))
         :else (throw (:error result#))))))

;; Uso:
(with-retry 3
  (processar-operacao-que-pode-falhar))</code></pre>
 <h5 id="estruturas-de-dados-como-ferramenta-principal">Estruturas de Dados como Ferramenta Principal</h5>
<p>O Capítulo 3 de &ldquo;<a href="https://www.braveclojure.com/">Clojure for the Brave and True</a>&rdquo;) destaca como as estruturas de dados fundamentais do Clojure (mapas, vetores, conjuntos) são projetadas para serem a principal ferramenta de abstração. Isso se reflete na abordagem de tratamento de erros:</p>
<h6 id="1-retornando">1. <strong>Retornando <code>nil</code> para Ausência de Valor</strong></h6>
<p>Em Clojure, <code>nil</code> é um cidadão de primeira classe que representa a ausência de valor de forma explícita e segura:</p>


  <pre><code class="language-clojure">(defn buscar-usuario [id]
  (cond
    (= id 1) {:nome &#34;João&#34; :idade 30}
    (= id 2) {:nome &#34;Maria&#34; :idade 25}
    :else nil))  ; Retorna nil para IDs não encontrados

;; Uso idiomático com when-let
(when-let [usuario (buscar-usuario 1)]
  (println &#34;Usuário encontrado:&#34; usuario))
;; =&gt; Usuário encontrado: {:nome João, :idade 30}

;; Com thread-first (-&gt;&gt;) para encadeamento
(-&gt;&gt; 1
     buscar-usuario
     (when-let [u] (println &#34;Idade:&#34; (:idade u))))
;; =&gt; Idade: 30</code></pre>
 <p><strong>Por que isso é idiomático em Clojure?</strong></p>
<ul>
<li><code>nil</code> é falso em um contexto booleano</li>
<li>Funções como <code>when-let</code> e <code>if-let</code> tornam o código conciso</li>
<li>A imutabilidade garante que <code>nil</code> não cause efeitos colaterais inesperados</li>
</ul>
<h6 id="2-mapas-como-estrutura-de-erro">2. <strong>Mapas como Estrutura de Erro</strong></h6>
<p>Para casos onde mais informações são necessárias, mapas são uma escolha natural em Clojure:</p>


  <pre><code class="language-clojure">(defn dividir [a b]
  (if (zero? b)
    {:error :divisao-por-zero
     :message &#34;Não é possível dividir por zero&#34;
     :dados {:a a :b b}}
    {:resultado (/ a b)}))

;; Uso com destructuring
(let [{:keys [resultado error message]} (dividir 10 2)]
  (if error
    (println &#34;Erro:&#34; message)
    (println &#34;Resultado:&#34; resultado)))
;; =&gt; Resultado: 5</code></pre>
 <p><strong>Vantagens desta abordagem:</strong></p>
<ul>
<li>Estrutura de dados rica que pode conter qualquer informação relevante</li>
<li>Fácil de estender com novos campos</li>
<li>Pode ser processada por funções genéricas de manipulação de mapas</li>
</ul>
<h6 id="3-biblioteca">3. <strong>Biblioteca <code>slingshot</code> para Exceções com Mais Dados</strong></h6>
<p>Para casos onde exceções são necessárias, o Clojure oferece a biblioteca <code>slingshot</code> que permite lançar e capturar mapas como exceções:</p>


  <pre><code class="language-clojure">(require &#39;[slingshot.slingshot :refer [try&#43; throw&#43;]])

(defn processar-arquivo [caminho]
  (try&#43;
    (if (.exists (java.io.File. caminho))
      (let [conteudo (slurp caminho)]
        {:status :sucesso
         :tamanho (count conteudo)
         :conteudo conteudo})
      (throw&#43; {:tipo :arquivo-nao-encontrado
               :caminho caminho
               :timestamp (java.util.Date.)}))
    (catch [:tipo :arquivo-nao-encontrado] {:keys [caminho]}
      (println &#34;Arquivo não encontrado:&#34; caminho)
      {:status :erro :codigo 404})
    (catch Object _
      (println &#34;Erro inesperado:&#34; (pr-str &amp;throw-context))
      {:status :erro :codigo 500})))</code></pre>
 <p><strong>Inspiração para JavaScript/TypeScript</strong></p>


  <pre><code class="language-typescript">// Usando tipos discriminados para erros
type FileResult = 
  | { status: &#39;success&#39;; size: number; content: string }
  | { status: &#39;error&#39;; code: number; message?: string };

async function processFile(path: string): Promise&lt;FileResult&gt; {
  try {
    const content = await fs.promises.readFile(path, &#39;utf-8&#39;);
    return {
      status: &#39;success&#39;,
      size: content.length,
      content
    };
  } catch (error) {
    if (error.code === &#39;ENOENT&#39;) {
      return {
        status: &#39;error&#39;,
        code: 404,
        message: `File not found: ${path}`
      };
    }
    return {
      status: &#39;error&#39;,
      code: 500,
      message: &#39;Internal server error&#39;
    };
  }
}

// Uso com pattern matching
const result = await processFile(&#39;data.txt&#39;);
if (result.status === &#39;success&#39;) {
  console.log(`File size: ${result.size} bytes`);
} else {
  console.error(`Error ${result.code}: ${result.message}`);
}</code></pre>
 <h5 id="princípios-fundamentais-do-tratamento-de-erros-em-clojure">Princípios Fundamentais do Tratamento de Erros em Clojure</h5>
<ol>
<li>
<p><strong>Preferência por Valores sobre Exceções</strong></p>
<ul>
<li>Erros são valores como qualquer outro</li>
<li>Fluxo de controle explícito através de funções</li>
<li>Facilita a composição e transformação de erros</li>
</ul>
</li>
<li>
<p><strong>Imutabilidade como Base</strong></p>
<ul>
<li>Dados de erro são imutáveis</li>
<li>Sem preocupação com estado compartilhado</li>
<li>Thread-safe por padrão</li>
</ul>
</li>
<li>
<p><strong>Funções Pequenas e Com Propósito Único</strong></p>
<ul>
<li>Cada função faz uma coisa bem</li>
<li>Erros são tratados próximo de onde ocorrem</li>
<li>Código mais fácil de testar e manter</li>
</ul>
</li>
<li>
<p><strong>Documentação através de Código</strong></p>
<ul>
<li>Assinaturas de funções claras</li>
<li>Estruturas de dados bem definidas</li>
<li>Comportamento previsível</li>
</ul>
</li>
</ol>
<p>Esta abordagem alinhada com os princípios funcionais do Clojure resulta em um código mais robusto, previsível e fácil de manter, onde o tratamento de erros é uma parte natural do fluxo do programa, não uma exceção ao fluxo normal.</p>
<ul>
<li>
<p><strong>Bibliotecas como <code>slingshot</code></strong>: Permitem lançar e capturar mapas como exceções, oferecendo mais estrutura do que exceções Java padrão, mas ainda usando o mecanismo de <code>try/catch</code>. Esta é uma abordagem híbrida que mantém a estrutura de dados do Clojure mesmo quando usando exceções:</p>


  <pre><code class="language-clojure">(require &#39;[slingshot.slingshot :refer [try&#43; throw&#43;]])

(defn processar-dados [dados]
  (try&#43;
    (if (empty? dados)
      (throw&#43; {:type :dados-vazios
              :message &#34;Nenhum dado para processar&#34;})
      {:ok (count dados)})
    (catch [:type :dados-vazios] {:keys [message]}
      {:error :processamento-falhou
       :message message})))

(processar-dados [])  ; =&gt; {:error :processamento-falhou, :message &#34;Nenhum dado para processar&#34;}
(processar-dados [1 2 3])  ; =&gt; {:ok 3}</code></pre>
 <p><strong>Inspiração para JavaScript/TypeScript</strong>:</p>


  <pre><code class="language-typescript">// Implementação similar ao slingshot
class StructuredError extends Error {
    constructor(
        public type: string,
        public details: Record&lt;string, unknown&gt;
    ) {
        super(details.message as string);
        this.name = &#39;StructuredError&#39;;
    }
}

function processarDados(dados: unknown[]): { ok: number } | { error: string; message: string } {
    try {
        if (dados.length === 0) {
            throw new StructuredError(&#39;dados-vazios&#39;, {
                message: &#39;Nenhum dado para processar&#39;
            });
        }
        return { ok: dados.length };
    } catch (e) {
        if (e instanceof StructuredError) {
            return {
                error: &#39;processamento-falhou&#39;,
                message: e.details.message as string
            };
        }
        throw e; // Re-throw unexpected errors
    }
}

// Uso
console.log(processarDados([])); // { error: &#39;processamento-falhou&#39;, message: &#39;Nenhum dado para processar&#39; }
console.log(processarDados([1, 2, 3])); // { ok: 3 }</code></pre>
 <p>A abordagem do <code>slingshot</code> é particularmente interessante porque:</p>
<ol>
<li>Mantém a estrutura de dados mesmo em erros</li>
<li>Permite pattern matching em exceções</li>
<li>Facilita a propagação de contexto com o erro</li>
<li>Mantém a compatibilidade com o sistema de exceções existente</li>
</ol>
<p>Em JavaScript/TypeScript, podemos implementar padrões similares usando classes de erro personalizadas e type guards, como mostrado no exemplo acima.</p>
</li>
</ul>
<hr>
<h3 id="o-princípio-crash-early">O Princípio &ldquo;Crash Early&rdquo;</h3>
<p>No livro &ldquo;<a href="https://a.co/d/8ZBw0ix">The Pragmatic Programmer</a>&rdquo;, Dave Thomas e Andy Hunt introduzem o princípio de <strong>&ldquo;Crash Early&rdquo;</strong> (ou &ldquo;Falhe Rápido&rdquo;), que é particularmente relevante para o tratamento de exceções. A ideia central é simples: quando algo der errado, falhe imediatamente e de forma visível, em vez de tentar continuar em um estado potencialmente inválido.</p>
<h4 id="por-que-falhar-rápido">Por que Falhar Rápido?</h4>
<ol>
<li>
<p><strong>Detecção Imediata de Problemas</strong></p>
<ul>
<li>Erros são identificados o mais cedo possível, perto de onde ocorreram</li>
<li>Facilita o diagnóstico e a correção de bugs</li>
<li>Evita que erros se propaguem e causem danos colaterais</li>
</ul>
</li>
<li>
<p><strong>Prevenção de Dados Corrompidos</strong></p>
<ul>
<li>Continuar a execução após um erro pode levar a estados inconsistentes</li>
<li>Melhor falhar de forma controlada do que processar dados inválidos</li>
<li>Reduz o risco de corrupção de dados persistente</li>
</ul>
</li>
<li>
<p><strong>Melhor Experiência de Desenvolvimento</strong></p>
<ul>
<li>Falhas rápidas tornam os bugs mais fáceis de reproduzir</li>
<li>Stack traces mais precisos e informativos</li>
<li>Reduz o tempo de depuração</li>
</ul>
</li>
</ol>
<h4 id="como-aplicar-o-crash-early-com-exceções">Como Aplicar o &ldquo;Crash Early&rdquo; com Exceções</h4>


  <pre><code class="language-c">// Ruim: Tenta continuar com valores inválidos
double calcularMedia(const std::vector&lt;int&gt;&amp; valores) {
    try {
        int soma = 0;
        for (int v : valores) {
            soma &#43;= v;
        }
        return static_cast&lt;double&gt;(soma) / valores.size();
    } catch (...) {
        // Retorna um valor padrão em caso de erro
        return 0.0; // Esconde o problema!
    }
}

// Bom: Falha cedo com mensagem clara
double calcularMedia(const std::vector&lt;int&gt;&amp; valores) {
    if (valores.empty()) {
        throw std::invalid_argument(&#34;Não é possível calcular média de vetor vazio&#34;);
    }
    
    int soma = 0;
    for (int v : valores) {
        // Verificação de overflow
        if ((v &gt; 0 &amp;&amp; soma &gt; std::numeric_limits&lt;int&gt;::max() - v) ||
            (v &lt; 0 &amp;&amp; soma &lt; std::numeric_limits&lt;int&gt;::min() - v)) {
            throw std::overflow_error(&#34;Estouro na soma dos valores&#34;);
        }
        soma &#43;= v;
    }
    
    return static_cast&lt;double&gt;(soma) / valores.size();
}</code></pre>
 <h4 id="quando-não-aplicar-o-crash-early">Quando Não Aplicar o &ldquo;Crash Early&rdquo;</h4>
<ol>
<li><strong>Sistemas Críticos</strong> onde a continuidade é essencial (ex: sistemas de controle de tráfego aéreo)</li>
<li><strong>Aplicações com Recuperação Automática</strong> que podem se recuperar de falhas</li>
<li><strong>Camadas de Alta Disponibilidade</strong> onde a interrupção do serviço é inaceitável</li>
</ol>
<h4 id="integração-com-outras-boas-práticas">Integração com Outras Boas Práticas</h4>
<ol>
<li>
<p><strong>Asserções para Invariantes</strong></p>


  <pre><code class="language-c">#include &lt;cassert&gt;

void processarDados(Dados* dados) {
    assert(dados != nullptr &amp;&amp; &#34;Ponteiro nulo não é permitido&#34;);
    // Resto do código...
}</code></pre>
 </li>
<li>
<p><strong>Validação de Entradas nas Fronteiras</strong></p>


  <pre><code class="language-c">class ServicoPagamento {
public:
    void processarPagamento(double valor, const std::string&amp; moeda) {
        if (valor &lt;= 0) {
            throw std::invalid_argument(&#34;Valor deve ser positivo&#34;);
        }
        if (moedasAceitas.find(moeda) == moedasAceitas.end()) {
            throw std::invalid_argument(&#34;Moeda não suportada: &#34; &#43; moeda);
        }
        // Processamento do pagamento...
    }

private:
    std::set&lt;std::string&gt; moedasAceitas{&#34;BRL&#34;, &#34;USD&#34;, &#34;EUR&#34;};
};</code></pre>
 </li>
<li>
<p><strong>Logs Informativos</strong></p>


  <pre><code class="language-c">void carregarConfiguracao(const std::string&amp; caminho) {
    std::ifstream arquivo(caminho);
    if (!arquivo) {
        std::string mensagem = &#34;Falha ao abrir arquivo: &#34; &#43; caminho;
        logger.erro(mensagem);
        throw std::runtime_error(mensagem);
    }
    // Carregar configuração...
}</code></pre>
 </li>
</ol>
<p>O princípio &ldquo;Crash Early&rdquo; complementa perfeitamente o uso adequado de exceções, garantindo que erros sejam tratados de forma clara e previsível, sem tentativas desesperadas de recuperação que podem piorar a situação.</p>
<h2 id="design-by-contract-e-programação-com-asserções">Design by Contract e Programação com Asserções</h2>
<h3 id="design-by-contract-dbc">Design by Contract (DbC)</h3>
<p>O conceito de <strong>Design by Contract</strong> (DbC), formalizado por <a href="https://en.wikipedia.org/wiki/Design_by_contract">Bertrand Meyer na linguagem Eiffel</a>, oferece uma estrutura poderosa para entender quando e como usar exceções. O DbC define um contrato explícito entre um componente e seus clientes, consistindo em:</p>
<ol>
<li><strong>Pré-condições</strong>: Obrigações que devem ser satisfeitas pelo chamador antes de invocar uma operação.</li>
<li><strong>Pós-condições</strong>: Garantias que a operação fornece quando as pré-condições são atendidas.</li>
<li><strong>Invariantes</strong>: Propriedades que devem ser mantidas ao longo do tempo.</li>
</ol>
<p>Como Bjarne Stroustrup destaca, quando uma função não consegue cumprir seu contrato, isso pode ser categorizado como:</p>
<ul>
<li><strong>Erro do chamador</strong>: Quando as pré-condições não são atendidas.</li>
<li><strong>Erro interno</strong>: Quando a função não consegue cumprir suas pós-condições apesar das pré-condições estarem satisfeitas.</li>
</ul>
<p>As exceções são o mecanismo natural para sinalizar violações de contrato. O uso inadequado de <code>try/catch</code> para fluxo lógico normal ignora esse conceito de contrato, onde o fluxo &ldquo;normal&rdquo; deveria satisfazer as pré-condições e esperar que as pós-condições sejam atendidas sem lançar exceções.</p>
<h4 id="exemplo-de-dbc-em-c">Exemplo de DbC em C++</h4>


  <pre><code class="language-c">class ContaBancaria {
    double saldo;
    
    // Invariante: saldo nunca pode ser negativo
    bool valido() const { return saldo &gt;= 0; }
    
public:
    void sacar(double valor) {
        // Pré-condição: valor deve ser positivo
        if (valor &lt;= 0) {
            throw std::invalid_argument(&#34;Valor do saque deve ser positivo&#34;);
        }
        
        // Pré-condição: saldo suficiente
        if (valor &gt; saldo) {
            throw std::domain_error(&#34;Saldo insuficiente&#34;);
        }
        
        double saldoAnterior = saldo;
        saldo -= valor;
        
        // Pós-condição: saldo foi reduzido corretamente
        if (!valido() || saldo != (saldoAnterior - valor)) {
            saldo = saldoAnterior; // Rollback
            throw std::logic_error(&#34;Falha na operação de saque&#34;);
        }
        
        // Invariante deve ser mantida
        assert(valido());
    }
};</code></pre>
 <h3 id="programação-com-asserções">Programação com Asserções</h3>
<p>A Programação com Asserções é uma prática complementar ao DbC, focada em verificar condições que &ldquo;nunca deveriam acontecer&rdquo; durante a execução:</p>
<ul>
<li><strong>Asserções</strong> são verificações de erros de programação, não de condições de erro em tempo de execução.</li>
<li>Quando uma asserção falha, isso indica um bug no código, não uma condição excepcional do ambiente.</li>
<li>Em C++, as asserções são tipicamente implementadas usando a macro <code>assert()</code> da biblioteca padrão.</li>
</ul>
<h4 id="quando-usar-asserções-vs-exceções">Quando Usar Asserções vs. Exceções</h4>
<table>
  <thead>
      <tr>
          <th><strong>Critério</strong></th>
          <th><strong>Asserções</strong></th>
          <th><strong>Exceções</strong></th>
      </tr>
  </thead>
  <tbody>
      <tr>
          <td><strong>Propósito</strong></td>
          <td>Encontrar bugs durante o desenvolvimento</td>
          <td>Lidar com condições excepcionais em produção</td>
      </tr>
      <tr>
          <td><strong>Impacto</strong></td>
          <td>Desativação em builds de produção</td>
          <td>Sempre ativas</td>
      </tr>
      <tr>
          <td><strong>Uso típico</strong></td>
          <td>Verificar invariantes internas</td>
          <td>Validar entradas externas</td>
      </tr>
      <tr>
          <td><strong>Exemplo</strong></td>
          <td><code>assert(ptr != nullptr)</code></td>
          <td><code>if (!arquivo) throw ...</code></td>
      </tr>
  </tbody>
</table>
<h4 id="exemplo-de-uso-de-asserções">Exemplo de Uso de Asserções</h4>


  <pre><code class="language-c">#include &lt;cassert&gt;

class BufferCircular {
    int* dados;
    size_t capacidade;
    size_t inicio = 0;
    size_t fim = 0;
    size_t contador = 0;
    
    bool cheio() const { return contador == capacidade; }
    bool vazio() const { return contador == 0; }
    
public:
    BufferCircular(size_t tamanho) : capacidade(tamanho) {
        assert(tamanho &gt; 0 &amp;&amp; &#34;Tamanho deve ser positivo&#34;);
        dados = new int[capacidade];
    }
    
    ~BufferCircular() {
        delete[] dados;
    }
    
    void inserir(int valor) {
        assert(!cheio() &amp;&amp; &#34;Buffer cheio - violação de pré-condição&#34;);
        
        dados[fim] = valor;
        fim = (fim &#43; 1) % capacidade;
        contador&#43;&#43;;
        
        assert(contador &lt;= capacidade &amp;&amp; &#34;Invariante violada&#34;);
    }
    
    int remover() {
        assert(!vazio() &amp;&amp; &#34;Buffer vazio - violação de pré-condição&#34;);
        
        int valor = dados[inicio];
        inicio = (inicio &#43; 1) % capacidade;
        contador--;
        
        assert(contador &gt;= 0 &amp;&amp; &#34;Invariante violada&#34;);
        return valor;
    }
};</code></pre>
 <h3 id="integrando-dbc-asserções-e-exceções">Integrando DbC, Asserções e Exceções</h3>
<ol>
<li><strong>DbC</strong> define o contrato formal entre componentes.</li>
<li><strong>Asserções</strong> verificam violações de contrato durante o desenvolvimento.</li>
<li><strong>Exceções</strong> lidam com violações de contrato em produção.</li>
</ol>
<p>Essas abordagens são complementares e, quando usadas em conjunto, resultam em código mais robusto e mais fácil de manter. O uso adequado de cada técnica ajuda a distinguir claramente entre erros de programação (que devem ser corrigidos) e condições excepcionais (que podem ser tratadas).</p>
<h2 id="desacoplamento-e-manutenibilidade">Desacoplamento e Manutenibilidade</h2>
<h3 id="o-impacto-do-trycatch-no-acoplamento">O Impacto do Try/Catch no Acoplamento</h3>
<p>O princípio <strong>ETC (Easier To Change)</strong> do livro <a href="https://a.co/d/8ZBw0ix">The Pragmatic Programmer</a> enfatiza que código desacoplado é mais fácil de modificar. O uso inadequado de <code>try/catch</code> para fluxo lógico normal pode criar dependências ocultas e contratos implícitos entre componentes, aumentando o acoplamento no sistema.</p>
<h4 id="problemas-do-acoplamento-por-exceções">Problemas do Acoplamento por Exceções</h4>
<ol>
<li>
<p><strong>Dependências Ocultas</strong>: Quando exceções são usadas para controle de fluxo, a relação entre o código que lança a exceção e o que a captura fica implícita, dificultando a compreensão do fluxo de execução.</p>
</li>
<li>
<p><strong>Contratos Implícitos</strong>: O uso de exceções para casos normais de uso cria contratos não documentados entre componentes, onde o comportamento esperado fica escondido na lógica de tratamento de erros.</p>
</li>
<li>
<p><strong>Dificuldade de Manutenção</strong>: Alterações em um componente podem quebrrar outros componentes que dependem de padrões específicos de lançamento de exceções.</p>
</li>
</ol>
<h4 id="exemplo-de-código-com-alto-acoplamento">Exemplo de Código com Alto Acoplamento</h4>


  <pre><code class="language-c">// Serviço de autenticação
class ServicoAutenticacao {
public:
    Usuario* autenticar(const std::string&amp; usuario, const std::string&amp; senha) {
        if (!usuarioExiste(usuario)) {
            throw UsuarioNaoEncontrado(usuario);
        }
        if (!senhaValida(usuario, senha)) {
            throw SenhaInvalida();
        }
        return obterUsuario(usuario);
    }
};

// Código cliente que usa o serviço
try {
    Usuario* user = servicoAutenticacao.autenticar(nomeUsuario, senha);
    // Fluxo de sucesso
} catch (const UsuarioNaoEncontrado&amp; e) {
    // Tratar usuário não encontrado
    mostrarMensagem(&#34;Usuário não existe&#34;);
} catch (const SenhaInvalida&amp; e) {
    // Tratar senha inválida
    mostrarMensagem(&#34;Senha incorreta&#34;);
}</code></pre>
 <p>Neste exemplo, o código cliente está fortemente acoplado aos tipos específicos de exceções lançadas pelo serviço de autenticação. Qualquer mudança nos tipos de exceções ou nas condições de lançamento pode quebrar o código cliente.</p>
<h4 id="alternativa-com-menos-acoplamento">Alternativa com Menos Acoplamento</h4>


  <pre><code class="language-c">// Resultado da autenticação
struct ResultadoAutenticacao {
    enum class Status { Sucesso, UsuarioNaoEncontrado, SenhaInvalida };
    Status status;
    std::optional&lt;Usuario*&gt; usuario;
    std::string mensagemErro;
};

// Serviço de autenticação modificado
class ServicoAutenticacao {
public:
    ResultadoAutenticacao autenticar(const std::string&amp; usuario, const std::string&amp; senha) {
        if (!usuarioExiste(usuario)) {
            return {ResultadoAutenticacao::Status::UsuarioNaoEncontrado, 
                   std::nullopt, 
                   &#34;Usuário não encontrado&#34;};
        }
        if (!senhaValida(usuario, senha)) {
            return {ResultadoAutenticacao::Status::SenhaInvalida,
                   std::nullopt,
                   &#34;Senha incorreta&#34;};
        }
        return {ResultadoAutenticacao::Status::Sucesso, 
               obterUsuario(usuario), 
               &#34;&#34;};
    }
};

// Código cliente melhorado
auto resultado = servicoAutenticacao.autenticar(nomeUsuario, senha);
if (resultado.status == ResultadoAutenticacao::Status::Sucesso) {
    // Fluxo de sucesso
    Usuario* user = *resultado.usuario;
} else {
    // Tratamento de erros
    mostrarMensagem(resultado.mensagemErro);
}</code></pre>
 <h2 id="programação-por-coincidência">Programação por Coincidência</h2>
<h3 id="o-perigo-de-confiar-em-comportamentos-não-intencionais">O Perigo de Confiar em Comportamentos Não Intencionais</h3>
<p>A <strong>Programação por Coincidência</strong> ocorre quando um desenvolvedor escreve código que &ldquo;funciona&rdquo;, mas sem entender completamente o porquê. No contexto de tratamento de exceções, isso pode acontecer quando:</p>
<ol>
<li>
<p><strong>Comportamento não documentado</strong>: O código depende de exceções específicas lançadas por bibliotecas terceiras em determinadas situações, sem garantia de que esse comportamento será mantido em versões futuras.</p>
</li>
<li>
<p><strong>Efeitos colaterais acidentais</strong>: O código funciona porque uma exceção é lançada em um caso específico, mas o desenvolvedor não entende completamente as condições que levam a esse lançamento.</p>
</li>
<li>
<p><strong>Falso entendimento do fluxo</strong>: O desenvolvedor pode acreditar que está lidando com um caso excepcional, quando na verdade está tratando um fluxo de negócios normal.</p>
</li>
</ol>
<h4 id="exemplo-de-programação-por-coincidência">Exemplo de Programação por Coincidência</h4>


  <pre><code class="language-c">try {
    // Suponha que processarArquivo() às vezes lança std::runtime_error
    // quando o arquivo existe mas está vazio, mas isso não está documentado
    Resultado resultado = processarArquivo(caminhoArquivo);
    return resultado;
} catch (const std::runtime_error&amp; e) {
    // O desenvolvedor assume que isso só acontece para arquivos vazios,
    // mas na verdade pode ocorrer por outros motivos
    return criarResultadoVazio();
}</code></pre>
 <p>Neste exemplo, o código está fazendo suposições perigosas sobre quando e por que uma exceção é lançada. Se o comportamento interno de <code>processarArquivo()</code> mudar em uma versão futura, o código pode começar a tratar incorretamente erros que deveriam ser reportados.</p>
<h4 id="como-evitar-programação-por-coincidência">Como Evitar Programação por Coincidência</h4>
<ol>
<li>
<p><strong>Documentação Clara</strong>: Sempre verifique a documentação para entender quando e por que as exceções são lançadas.</p>
</li>
<li>
<p><strong>Testes Abrangentes</strong>: Escreva testes que verifiquem explicitamente os comportamentos esperados, não apenas os casos de sucesso.</p>
</li>
<li>
<p><strong>Fail Fast</strong>: Se uma condição inesperada for encontrada, falhe de forma clara e visível em vez de tentar continuar com um estado potencialmente inválido.</p>
</li>
<li>
<p><strong>Verificação Explícita</strong>: Em vez de depender de exceções para fluxo normal, use verificações explícitas sempre que possível.</p>
</li>
<li>
<p><strong>Logs Informativos</strong>: Adicione logs detalhados que expliquem o motivo pelo qual uma exceção foi lançada, facilitando a depuração.</p>
</li>
</ol>
<h2 id="configuração-como-metadados">Configuração como Metadados</h2>
<h3 id="externalizando-regras-de-negócio">Externalizando Regras de Negócio</h3>
<p>O princípio <strong>&ldquo;Policy as Metadata&rdquo;</strong> do livro &ldquo;The Pragmatic Programmer&rdquo; sugere que muitas condições especiais que são frequentemente tratadas com estruturas de controle complexas (como <code>try/catch</code> ou <code>if/else</code> aninhados) podem ser melhor gerenciadas como configurações externas. Isso é particularmente relevante para regras de negócio que podem mudar com o tempo.</p>
<h4 id="benefícios-da-abordagem-baseada-em-configuração">Benefícios da Abordagem Baseada em Configuração</h4>
<ol>
<li><strong>Maior Flexibilidade</strong>: Regras podem ser alteradas sem modificar o código-fonte.</li>
<li><strong>Código Mais Limpo</strong>: Reduz a complexidade ciclomática ao eliminar múltiplos caminhos condicionais.</li>
<li><strong>Melhor Manutenibilidade</strong>: Separa claramente o &ldquo;o quê&rdquo; (a política) do &ldquo;como&rdquo; (a implementação).</li>
<li><strong>Testabilidade Mais Fácil</strong>: Permite testar diferentes cenários alterando apenas a configuração.</li>
</ol>
<h4 id="exemplo-sistema-de-permissões-baseado-em-configuração">Exemplo: Sistema de Permissões Baseado em Configuração</h4>


  <pre><code class="language-c">// Configuração em JSON (pode ser carregada de um arquivo)
{
    &#34;permissoes&#34;: [
        {
            &#34;recurso&#34;: &#34;documento&#34;,
            &#34;acoes&#34;: [&#34;ler&#34;, &#34;editar&#34;, &#34;excluir&#34;],
            &#34;regras&#34;: [
                {
                    &#34;tipo&#34;: &#34;funcao&#34;,
                    &#34;nome&#34;: &#34;eDono&#34;,
                    &#34;mensagem&#34;: &#34;Apenas o dono pode editar este documento&#34;
                },
                {
                    &#34;tipo&#34;: &#34;role&#34;,
                    &#34;nome&#34;: &#34;admin&#34;,
                    &#34;mensagem&#34;: &#34;Apenas administradores podem excluir documentos&#34;
                }
            ]
        }
    ]
}

// Código que usa a configuração
class GerenciadorPermissoes {
    ConfiguracaoPermissoes config_;
    
public:
    GerenciadorPermissoes(const ConfiguracaoPermissoes&amp; config) : config_(config) {}
    
    ResultadoValidacao verificarPermissao(
        const Usuario&amp; usuario, 
        const std::string&amp; recurso, 
        const std::string&amp; acao) 
    {
        // Encontra as regras para o recurso e ação solicitados
        auto regras = config_.encontrarRegras(recurso, acao);
        
        // Aplica as regras em sequência
        for (const auto&amp; regra : regras) {
            if (!aplicarRegra(usuario, regra)) {
                return {false, regra.mensagem};
            }
        }
        
        return {true, &#34;&#34;};
    }
    
private:
    bool aplicarRegra(const Usuario&amp; usuario, const RegraPermissao&amp; regra) {
        if (regra.tipo == &#34;funcao&#34;) {
            // Verifica funções específicas do usuário
            return usuario.temFuncao(regra.nome);
        } else if (regra.tipo == &#34;role&#34;) {
            // Verifica papéis do usuário
            return usuario.temRole(regra.nome);
        }
        return false;
    }
};

// Uso no código principal
GerenciadorPermissoes gerenciador(carregarConfiguracao(&#34;permissoes.json&#34;));

// Em vez de:
// try {
//     verificarPermissao(usuario, documento, &#34;editar&#34;);
// } catch (const SemPermissaoException&amp; e) {
//     // Tratar erro
// }

// Faça:
auto resultado = gerenciador.verificarPermissao(usuario, &#34;documento&#34;, &#34;editar&#34;);
if (!resultado.sucesso) {
    mostrarErro(resultado.mensagem);
    return;
}</code></pre>
 <h2 id="testabilidade-e-caminhos-de-erro">Testabilidade e Caminhos de Erro</h2>
<h3 id="a-importância-de-testar-cenários-de-erro">A Importância de Testar Cenários de Erro</h3>
<p>O princípio <strong>&ldquo;Test Your Software, or Your Users Will&rdquo;</strong> enfatiza a importância de testar explicitamente os caminhos de erro. Quando <code>try/catch</code> é usado para controle de fluxo lógico, esses caminhos se tornam mais difíceis de testar de forma isolada e clara.</p>
<h4 id="desafios-no-teste-de-código-com-exceções">Desafios no Teste de Código com Exceções</h4>
<ol>
<li><strong>Abstração de Dependências</strong>: Código que lança exceções pode ser difícil de testar em isolamento.</li>
<li><strong>Cobertura de Código</strong>: Caminhos de exceção podem ser negligenciados nos testes.</li>
<li><strong>Clareza dos Testes</strong>: Testes que verificam comportamentos excepcionais podem ser menos legíveis.</li>
</ol>
<h4 id="estratégias-para-melhor-testabilidade">Estratégias para Melhor Testabilidade</h4>
<ol>
<li>
<p><strong>Use Objetos Falsos (Mocks/Stubs)</strong></p>


  <pre><code class="language-c">class ServicoExterno {
public:
    virtual ~ServicoExterno() = default;
    virtual Dados consultar(const std::string&amp; id) = 0;
};

// Mock para testes
class MockServicoExterno : public ServicoExterno {
    std::optional&lt;Dados&gt; dadosParaRetornar;
    std::exception_ptr excecaoParaLancar;
public:
    void configurarResposta(const Dados&amp; dados) {
        dadosParaRetornar = dados;
        excecaoParaLancar = nullptr;
    }

    void configurarFalha(const std::string&amp; mensagem) {
        excecaoParaLancar = std::make_exception_ptr(
            std::runtime_error(mensagem));
        dadosParaRetornar = std::nullopt;
    }

    Dados consultar(const std::string&amp;) override {
        if (excecaoParaLancar) {
            std::rethrow_exception(excecaoParaLancar);
        }
        return *dadosParaRetornar;
    }
};</code></pre>
 </li>
<li>
<p><strong>Testes Específicos para Caminhos de Erro</strong></p>


  <pre><code class="language-c">TEST(TesteProcessador, DeveLidarComFalhaDeConexao) {
    MockServicoExterno mock;
    mock.configurarFalha(&#34;Falha na conexão&#34;);

    Processador p(mock);

    // Verifica se o processador lida corretamente com a falha
    auto resultado = p.processar(&#34;123&#34;);
    EXPECT_FALSE(resultado.sucesso);
    EXPECT_EQ(resultado.erro, &#34;Erro ao acessar o serviço externo&#34;);
}</code></pre>
 </li>
<li>
<p><strong>Use Tipos de Retorno em Vez de Exceções para Fluxo Normal</strong></p>


  <pre><code class="language-c">// Em vez de lançar exceções para casos esperados
struct ResultadoProcessamento {
    bool sucesso;
    std::string erro;
    Dados dados;
};

ResultadoProcessamento processar(const Entrada&amp; entrada) {
    if (!validar(entrada)) {
        return {false, &#34;Entrada inválida&#34;, {}};
    }
    // Processamento...
    return {true, &#34;&#34;, resultado};
}

// Teste fica mais claro
TEST(TesteProcessador, DeveRejeitarEntradaInvalida) {
    Processador p;
    auto resultado = p.processar(entradaInvalida);
    EXPECT_FALSE(resultado.sucesso);
    EXPECT_EQ(resultado.erro, &#34;Entrada inválida&#34;);
}</code></pre>
 </li>
<li>
<p><strong>Testes de Propriedades</strong></p>
<ul>
<li>Em vez de testar apenas casos específicos, teste propriedades que devem sempre ser verdadeiras.</li>
<li>Útil para verificar se o comportamento de tratamento de erros é consistente.</li>
</ul>
</li>
<li>
<p><strong>Testes de Integração Controlados</strong></p>
<ul>
<li>Use ambientes de teste controlados para simular falhas em sistemas externos.</li>
<li>Verifique se o sistema se recupera adequadamente de falhas transitórias.</li>
</ul>
</li>
</ol>
<hr>
<h2 id="referências">Referências</h2>
<ol>
<li>
<p><a href="https://a.co/d/8ZBw0ix"><strong>&ldquo;The Pragmatic Programmer: Your Journey to Mastery&rdquo;</strong> - David Thomas &amp; Andrew Hunt</a><br>
<em>Apresenta o princípio &ldquo;Crash Early&rdquo; e outras práticas essenciais para programação profissional, incluindo tratamento de erros e resiliência em sistemas.</em></p>
</li>
<li>
<p><a href="https://a.co/d/1L2Bwz4"><strong>&ldquo;Effective Modern C++: 42 Specific Ways to Improve Your Use of C++11 and C++14&rdquo;</strong> - Scott Meyers</a><br>
<em>Discute técnicas modernas de C++, incluindo o uso correto de exceções e alternativas como <code>std::optional</code>.</em></p>
</li>
<li>
<p><a href="https://a.co/d/3Wy2dFE"><strong>&ldquo;Programming: Principles and Practice Using C++&rdquo;</strong> - Bjarne Stroustrup</a><br>
<em>O criador do C++ explica fundamentos da linguagem, incluindo tratamento de erros e quando usar exceções.</em></p>
</li>
<li>
<p><a href="https://a.co/d/a4zoUcs"><strong>&ldquo;The Rust Programming Language&rdquo; (Livro Oficial)</strong> - Steve Klabnik &amp; Carol Nichols</a><br>
<em>Explica o sistema de <code>Result</code> e <code>Option</code> do Rust, que evita exceções.</em></p>
</li>
<li>
<p><a href="https://a.co/d/4geTFbr"><strong>&ldquo;Clojure for the Brave and True&rdquo;</strong> - Daniel Higginbotham</a><br>
<em>Aborda a filosofia de tratamento de erros em Clojure usando valores e mapas.</em></p>
</li>
<li>
<p><a href="https://ziglang.org/documentation/"><strong>&ldquo;Zig Programming Language Documentation&rdquo;</strong> (Online)</a><br>
<em>Explica o sistema único de erros como valores em Zig.</em></p>
</li>
<li>
<p><a href="https://a.co/d/8oEH9z4"><strong>&ldquo;Designing Data-Intensive Applications&rdquo;</strong> - Martin Kleppmann</a><br>
<em>Discute tolerância a falhas em sistemas distribuídos, complementando o conceito de &ldquo;graceful failure&rdquo;.</em></p>
</li>
<li>
<p><a href="https://a.co/d/66ya4UP"><strong>&ldquo;Release It!: Design and Deploy Production-Ready Software&rdquo;</strong> - Michael T. Nygard</a><br>
<em>Ensina padrões como &ldquo;Circuit Breaker&rdquo; para lidar com erros em produção.</em></p>
</li>
<li>
<p><a href="https://a.co/d/5bg0IIB"><strong>&ldquo;Functional Light JavaScript&rdquo;</strong> - Kyle Simpson</a><br>
<em>Mostra como aplicar conceitos funcionais (incluindo tratamento de erros sem exceções) em JavaScript.</em></p>
</li>
<li>
<p><a href="https://a.co/d/9S37n8W"><strong>&ldquo;Domain Modeling Made Functional&rdquo;</strong> - Scott Wlaschin</a><br>
<em>Usa F# para demonstrar como tipos como <code>Result</code> podem modelar erros de forma explícita.</em></p>
</li>
</ol>

    </div>
    
    
    <div class="post-comments">
        <div id="disqus_thread"></div>
<script>
    window.disqus_config = function () {
    
    
    
    };
    (function() {
        if (["localhost", "127.0.0.1"].indexOf(window.location.hostname) != -1) {
            document.getElementById('disqus_thread').innerHTML = 'Disqus comments not available by default when the website is previewed locally.';
            return;
        }
        var d = document, s = d.createElement('script'); s.async = true;
        s.src = '//' + "scovl" + '.disqus.com/embed.js';
        s.setAttribute('data-timestamp', +new Date());
        (d.head || d.body).appendChild(s);
    })();
</script>
<noscript>Please enable JavaScript to view the <a href="https://disqus.com/?ref_noscript">comments powered by Disqus.</a></noscript>
<a href="https://disqus.com" class="dsq-brlink">comments powered by <span class="logo-disqus">Disqus</span></a>
    </div>
    
</article>

        </main>
        
        
        
        <footer class="site-footer">
    <div class="footer-inner">
        <div class="footer-content">
            <div class="copyright">
                &copy; 2025 Vitor Lobo
            </div>
            
            <div class="social-links">
                
                <a href="https://github.com/scovl" target="_blank" rel="noopener noreferrer" class="social-link">
                    GitHub
                </a>
                
                
                
                <a href="https://linkedin.com/in/vitor-lobo" target="_blank" rel="noopener noreferrer" class="social-link">
                    LinkedIn
                </a>
                
                
                
                <a href="mailto:lobocode@gmail.com" class="social-link">
                    Email
                </a>
                

                
                <a href="https://hachyderm.io/@lobocode" target="_blank" rel="noopener noreferrer" class="social-link">
                    Mastodon
                </a>
                

                
                <a href="https://scovl.github.io/index.xml" target="_blank" rel="noopener noreferrer" class="social-link">
                    RSS
                </a>
                

            </div>
        </div>
    </div>
</footer>


<script src="/js/code-escaper.js"></script>


<script>
  document.addEventListener("DOMContentLoaded", function() {
    
    if (typeof Prism !== 'undefined') {
      Prism.highlightAll();
    }
  });
</script>

</body>
</html> 
        
    </div>
    
    
    <script src="/js/main.js"></script>
    
    
    
</body>
</html> 